Workbook

Sheet Export Summary
B3: This document was exported from Numbers. Each table was converted to an Excel worksheet. All other objects on each Numbers sheet were placed on separate worksheets. Please be aware that formula calculations may differ in Excel.
B7: Numbers Sheet Name | C7: Numbers Table Name | D7: Excel Worksheet Name
B9: DASHBOARD
C10: Table 1 | D10: DASHBOARD
B11: QR Code
C12: Table 1 | D12: QR Code
B13: PLANO DE AÇÃO GERAL
C14: Table 1 | D14: PLANO DE AÇÃO GERAL
B15: BALANÇO
C16: Table 1 | D16: BALANÇO
B17: Endividamento
C18: Table 1 | D18: Endividamento
B19: Fluxo de Caixa
C20: Table 1 | D20: Fluxo de Caixa
B21: DRE
C22: Table 1 | D22: DRE
B23: Base DRE
C24: Table 1 | D24: Base DRE
B25: Base DRE Arquivo
C26: Table 1 | D26: Base DRE Arquivo
B27: Precificação
C28: Table 1 | D28: Precificação
B29: MARKUP
C30: Table 1 | D30: MARKUP
B31: INDUSTRIA
C32: Table 1 | D32: INDUSTRIA
B33: TABELA DE PREÇOS
C34: Table 1 | D34: TABELA DE PREÇOS
B35: SERVIÇO
C36: Table 1 | D36: SERVIÇO
B37: CUSTO FIXO
C38: Table 1 | D38: CUSTO FIXO
B39: CUSTO VARIAVEL
C40: Table 1 | D40: CUSTO VARIAVEL
B41: 1.Financeiro
C42: Table 1 | D42: 1.Financeiro
B43: 2.Comercial
C44: Table 1 | D44: 2.Comercial
B45: 3.Marketing
C46: Table 1 | D46: 3.Marketing
...

Sheet DASHBOARD

Sheet QR Code

Sheet PLANO DE AÇÃO GERAL
A1: PLANO DE AÇÃO
A7: Item | B7: Ação | C7: Responsável | D7: PRAZO | E7: DATA EXEC | F7: Status | G7: Melhoria Esperada | H7: Observação
F8: {=IF(D8="","AGUARDANDO",IF(E8<>"","CONCLUIDO",IF(TODAY()<=D8,"EM ANDAMENTO",IF(TODAY()>D8,"ATRASADO","CONCLUIDO"))))} -> AGUARDANDO
F9: {=IF(D9="","AGUARDANDO",IF(TODAY()<=D9,"EM ANDAMENTO",IF(TODAY()>D9,"ATRASADO","CONCLUIDO")))} -> AGUARDANDO
F10: {=IF(D10="","AGUARDANDO",IF(TODAY()<=D10,"EM ANDAMENTO",IF(TODAY()>D10,"ATRASADO","CONCLUIDO")))} -> AGUARDANDO
F11: {=IF(D11="","AGUARDANDO",IF(TODAY()<=D11,"EM ANDAMENTO",IF(TODAY()>D11,"ATRASADO","CONCLUIDO")))} -> AGUARDANDO
F12: {=IF(D12="","AGUARDANDO",IF(TODAY()<=D12,"EM ANDAMENTO",IF(TODAY()>D12,"ATRASADO","CONCLUIDO")))} -> AGUARDANDO
F13: {=IF(D13="","AGUARDANDO",IF(TODAY()<=D13,"EM ANDAMENTO",IF(TODAY()>D13,"ATRASADO","CONCLUIDO")))} -> AGUARDANDO
F14: {=IF(D14="","AGUARDANDO",IF(TODAY()<=D14,"EM ANDAMENTO",IF(TODAY()>D14,"ATRASADO","CONCLUIDO")))} -> AGUARDANDO
F15: {=IF(D15="","AGUARDANDO",IF(TODAY()<=D15,"EM ANDAMENTO",IF(TODAY()>D15,"ATRASADO","CONCLUIDO")))} -> AGUARDANDO
F16: {=IF(D16="","AGUARDANDO",IF(TODAY()<=D16,"EM ANDAMENTO",IF(TODAY()>D16,"ATRASADO","CONCLUIDO")))} -> AGUARDANDO
F17: {=IF(D17="","AGUARDANDO",IF(TODAY()<=D17,"EM ANDAMENTO",IF(TODAY()>D17,"ATRASADO","CONCLUIDO")))} -> AGUARDANDO
F18: {=IF(D18="","AGUARDANDO",IF(TODAY()<=D18,"EM ANDAMENTO",IF(TODAY()>D18,"ATRASADO","CONCLUIDO")))} -> AGUARDANDO
F19: {=IF(D19="","AGUARDANDO",IF(TODAY()<=D19,"EM ANDAMENTO",IF(TODAY()>D19,"ATRASADO","CONCLUIDO")))} -> AGUARDANDO
F20: {=IF(D20="","AGUARDANDO",IF(TODAY()<=D20,"EM ANDAMENTO",IF(TODAY()>D20,"ATRASADO","CONCLUIDO")))} -> AGUARDANDO
... F28: {=IF(D28="","AGUARDANDO",IF(TODAY()<=D28,"EM ANDAMENTO",IF(TODAY()>D28,"ATRASADO","CONCLUIDO")))} -> AGUARDANDO

Sheet BALANÇO
C7: ATIVO | H7: PASSIVO
E8: Total do Ativo | F8: {=SUM(F9:F26)} -> 0 | I8: Total Passivo | J8: {=SUM(J9:J19)} -> 0
C9: Ativo | D9: Disponíveis | E9: Clientes a Receber ( - taxas) | H9: Passivo | I9: Fornecedores
E10: Conta Corrente | I10: Contas fixas a pagar
I11: Empréstimos
I17: Funcionários (última folha + 70%)
D20: Recursos Estocados | E20: Estoque
E21: Investimentos (aplicação) | H21: TOTAL DO ATIVO | J21: {=F8} -> 0
H23: TOTAL DO PASSIVO | J23: {=J8} -> 0
H25: PATRIMÔNIO LÍQUIDO | J25: {=J21-J23} -> 0

Sheet Endividamento
B8: SALDO DEVEDOR TOTAL | D8: {=E18} -> 0
B11: MODALIDADE | C11: Numero | D11: VALOR CONTRATADO | E11: SALDO DEVEDOR | F11: TX | G11: VENCIMENTO | H11: PARCELA | I11: PARCELAS PAGAS | J11: PROXIMAS PARCELAS | K11: ULTIMA PARCELA
B12: Banco 01 | C12: XXXXX
B13: Banco 02 | C13: XXXXX
B14: Banco 03 | C14: XXXXX
B15: Banco 04 | C15: XXXXX
B18: TOTAL | D18: {=SUM(D12:D17)} -> 0 | E18: {=SUM(E12:E17)} -> 0

Sheet Fluxo de Caixa
D8: SALDO INICIAL DO PLAN | F8: 0
C10: PLANEJADO | D10: RECEITAS | F10: 46023 | G10: 46054 | H10: 46082 | I10: 46113 | J10: 46143 | K10: 46174 | L10: 46204 | M10: 46235 | N10: 46266 | O10: 46296 | P10: 46327 | Q10: 46357
D11: RECEBIVEIS MENSAL | F11: {=SUM(F12:F21)} -> 0 | G11: {=SUM(G12:G21)} -> 0 | H11: {=SUM(H12:H21)} -> 0 | I11: {=SUM(I12:I21)} -> 0 | J11: {=SUM(J12:J21)} -> 5000 | K11: {=SUM(K12:K21)} -> 6000 | L11: {=SUM(L12:L21)} -> 4000 | M11: {=SUM(M12:M21)} -> 0 | ... Q11: {=SUM(Q12:Q21)} -> 0
D12: VENDAS A VISTA
D13: VENDAS EM 30 DIAS
D14: VENDAS EM 60 DIAS
D20: RESERVA DE EMERGÊNCIA | J20: 5000 | K20: 6000 | L20: 4000
D22: DESPESAS | F22: {=F10} -> 46023 | G22: {=G10} -> 46054 | H22: {=H10} -> 46082 | I22: {=I10} -> 46113 | J22: {=J10} -> 46143 | K22: {=K10} -> 46174 | L22: {=L10} -> 46204 | M22: {=M10} -> 46235 | ... Q22: {=Q10} -> 46357
D23: COMPROMISSO MENSAL | E23: % | F23: {=SUM(F24:F39)} -> 0 | G23: {=SUM(G24:G39)} -> 0 | H23: {=SUM(H24:H39)} -> 0 | I23: {=SUM(I24:I39)} -> 0 | J23: {=SUM(J24:J39)} -> 0 | K23: {=SUM(K24:K39)} -> 0 | L23: {=SUM(L24:L39)} -> 0 | M23: {=SUM(M24:M39)} -> 0 | ... Q23: {=SUM(Q24:Q39)} -> 0
D24: DESPESAS FIXAS
D25: DESPESAS VARIÁVEIS | E25: 0.2
D26: CUSTOS VARIÁVEIS | E26: 0.4
D27: DESPESAS FINANCEIRAS E OUTROS
D28: DISTRIBUIÇÃO DE LUCRO E PROLABORE
D38: RETIRADA PARA RESERVA DE EMERGÊNCIA
D41: RESULTADO RECEITAS - DESPESAS | F41: {=F11-F23} -> 0 | G41: {=G11-G23} -> 0 | H41: {=H11-H23} -> 0 | I41: {=I11-I23} -> 0 | J41: {=J11-J23} -> 5000 | K41: {=K11-K23} -> 6000 | L41: {=L11-L23} -> 4000 | M41: {=M11-M23} -> 0 | ... Q41: {=Q11-Q23} -> 0
D43: RESERVA DE EMERGENCIA (3 MESES DO CF) | F43: {=15000+F38-F20} -> 15000 | G43: {=F43+G38-G20} -> 15000 | H43: {=G43+H38-H20} -> 15000 | I43: {=H43+I38-I20} -> 15000 | J43: {=I43+J38-J20} -> 10000 | K43: {=J43+K38-K20} -> 4000 | L43: {=K43+L38-L20} -> 0 | M43: {=L43+M38-M20} -> 0 | N43: {=M43+N38-N20} -> 0 | ... Q43: {=P43+Q38-Q20} -> 0
D45: SALDO ACUMULADO | F45: {=F41+F8} -> 0 | G45: {=G41+F45} -> 0 | H45: {=H41+G45} -> 0 | I45: {=I41+H45} -> 0 | J45: {=J41+I45} -> 5000 | K45: {=K41+J45} -> 11000 | L45: {=L41+K45} -> 15000 | M45: {=M41+L45} -> 15000 | N45: {=N41+M45} -> 15000 | ... Q45: {=Q41+P45} -> 15000
C50: PREVISÃO DE RECEBÍVEIS A PRAZO | F50: Á Vista | G50: 30 Dias | H50: 60 Dias
C52: % | D52: FATURAMENTO TOTAL
C53: 0.4 | D53: VENDAS A VISTA | F53: {=F$52*$C53} -> 0 | G53: {=G$52*$C53} -> 0 | H53: {=H$52*$C53} -> 0
C54: 0.3 | D54: VENDAS EM 30 DIAS | F54: {=F$52*$C54} -> 0 | G54: {=G$52*$C54} -> 0 | H54: {=H$52*$C54} -> 0
C55: 0.3 | D55: VENDAS EM 60 DIAS | F55: {=F$52*$C55} -> 0 | G55: {=G$52*$C55} -> 0 | H55: {=H$52*$C55} -> 0

Sheet DRE
D2: SELECIONE O CENTRO DE CUSTO | H2: *
H4: {=H2} -> *
C6: DEMONSTRATIVO DE RESULTADO | D6: 2026 | F6: 2026 | H6: 2026 | J6: 2026 | L6: 2026 | N6: 2026 | P6: 2026 | R6: 2026 | T6: 2026 | V6: 2026 | X6: 2026 | Z6: 2026
C7: CONSOLIDADO | D7: 46054 | E7: % | F7: 46082 | G7: % | H7: 46113 | I7: % | J7: 46143 | K7: % | L7: 46173 | M7: % | N7: 46203 | O7: % | P7: 46233 | Q7: % | R7: 46263 | S7: % | T7: 46293 | U7: % | V7: 46323 | W7: % | X7: 46353 | Y7: % | Z7: 46383 | AA7: %
C8: ( = ) Receitas Operacionais | D8: {=D9} -> 0 | E8: {=_xlfn.IFERROR(D8/D$8,"")} | F8: {=F9} -> 0 | G8: {=_xlfn.IFERROR(F8/F$8,"")} | H8: {=H9} -> 0 | I8: {=_xlfn.IFERROR(H8/H$8,"")} | J8: {=J9} -> 0 | K8: {=_xlfn.IFERROR(J8/J$8,"")} | L8: {=L9} -> 0 | M8: {=_xlfn.IFERROR(L8/L$8,"")} | N8: {=N9} -> 0 | O8: {=_xlfn.IFERROR(N8/N$8,"")} | P8: {=P9} -> 0 | Q8: {=_xlfn.IFERROR(P8/P$8,"")} | R8: {=R9} -> 0 | S8: {=_xlfn.IFERROR(R8/R$8,"")} | T8: {=T9} -> 0 | U8: {=_xlfn.IFERROR(T8/T$8,"")} | V8: {=V9} -> 0 | W8: {=_xlfn.IFERROR(V8/V$8,"")} | X8: {=X9} -> 0 | Y8: {=_xlfn.IFERROR(X8/X$8,"")} | Z8: {=Z9} -> 0 | AA8: {=_xlfn.IFERROR(Z8/Z$8,"")}
B9: 1. | C9: ( + ) Receita de Vendas de Produtos e Serviços | D9: {=SUM(D10:D12)} -> 0 | E9: {=_xlfn.IFERROR(D9/D$8,"")} | F9: {=SUM(F10:F12)} -> 0 | G9: {=_xlfn.IFERROR(F9/F$8,"")} | H9: {=SUM(H10:H12)} -> 0 | I9: {=_xlfn.IFERROR(H9/H$8,"")} | J9: {=SUM(J10:J12)} -> 0 | K9: {=_xlfn.IFERROR(J9/J$8,"")} | L9: {=SUM(L10:L12)} -> 0 | M9: {=_xlfn.IFERROR(L9/L$8,"")} | N9: {=SUM(N10:N12)} -> 0 | O9: {=_xlfn.IFERROR(N9/N$8,"")} | P9: {=SUM(P10:P12)} -> 0 | Q9: {=_xlfn.IFERROR(P9/P$8,"")} | R9: {=SUM(R10:R12)} -> 0 | S9: {=_xlfn.IFERROR(R9/R$8,"")} | T9: {=SUM(T10:T12)} -> 0 | U9: {=_xlfn.IFERROR(T9/T$8,"")} | V9: {=SUM(V10:V12)} -> 0 | W9: {=_xlfn.IFERROR(V9/V$8,"")} | X9: {=SUM(X10:X12)} -> 0 | Y9: {=_xlfn.IFERROR(X9/X$8,"")} | Z9: {=SUM(Z10:Z12)} -> 0 | AA9: {=_xlfn.IFERROR(Z9/Z$8,"")}
B10: RECEITA | C10: Receita de Vendas - Produtos | D10: {=_xlfn.SUMIFS('Base DRE'!$E1:$E625,'Base DRE'!$I1:$I625,D$7,'Base DRE'!$L1:$L625,$C10,'Base DRE'!$K1:$K625,$H$2)} -> 0 | F10: {=_xlfn.SUMIFS('Base DRE'!$E1:$E625,'Base DRE'!$I1:$I625,F$7,'Base DRE'!$L1:$L625,$C10,'Base DRE'!$K1:$K625,$H$2)} -> 0 | H10: {=_xlfn.SUMIFS('Base DRE'!$E1:$E625,'Base DRE'!$I1:$I625,H$7,'Base DRE'!$L1:$L625,$C10,'Base DRE'!$K1:$K625,$H$2)} -> 0 | J10: {=_xlfn.SUMIFS('Base DRE'!$E1:$E625,'Base DRE'!$I1:$I625,J$7,'Base DRE'!$L1:$L625,$C10,'Base DRE'!$K1:$K625,$H$2)} -> 0 | L10: {=_xlfn.SUMIFS('Base DRE'!$E1:$E625,'Base DRE'!$I1:$I625,L$7,'Base DRE'!$L1:$L625,$C10,'Base DRE'!$K1:$K625,$H$2)} -> 0 | N10: {=_xlfn.SUMIFS('Base DRE'!$E1:$E625,'Base DRE'!$I1:$I625,N$7,'Base DRE'!$L1:$L625,$C10,'Base DRE'!$K1:$K625,$H$2)} -> 0 | P10: {=_xlfn.SUMIFS('Base DRE'!$E1:$E625,'Base DRE'!$I1:$I625,P$7,'Base DRE'!$L1:$L625,$C10,'Base DRE'!$K1:$K625,$H$2)} -> 0 | R10: {=_xlfn.SUMIFS('Base DRE'!$E1:$E625,'Base DRE'!$I1:$I625,R$7,'Base DRE'!$L1:$L625,$C10,'Base DRE'!$K1:$K625,$H$2)} -> 0 | T10: {=_xlfn.SUMIFS('Base DRE'!$E1:$E625,'Base DRE'!$I1:$I625,T$7,'Base DRE'!$L1:$L625,$C10,'Base DRE'!$K1:$K625,$H$2)} -> 0 | V10: {=_xlfn.SUMIFS('Base DRE'!$E1:$E625,'Base DRE'!$I1:$I625,V$7,'Base DRE'!$L1:$L625,$C10,'Base DRE'!$K1:$K625,$H$2)} -> 0 | X10: {=_xlfn.SUMIFS('Base DRE'!$E1:$E625,'Base DRE'!$I1:$I625,X$7,'Base DRE'!$L1:$L625,$C10,'Base DRE'!$K1:$K625,$H$2)} -> 0 | Z10: {=_xlfn.SUMIFS('Base DRE'!$E1:$E625,'Base DRE'!$I1:$I625,Z$7,'Base DRE'!$L1:$L625,$C10,'Base DRE'!$K1:$K625,$H$2)} -> 0
B11: RECEITA | C11: Receita de Vendas - Serviços | D11: {=_xlfn.SUMIFS('Base DRE'!$E1:$E625,'Base DRE'!$I1:$I625,D$7,'Base DRE'!$L1:$L625,$C11,'Base DRE'!$K1:$K625,$H$2)} -> 0 | F11: {=_xlfn.SUMIFS('Base DRE'!$E1:$E625,'Base DRE'!$I1:$I625,F$7,'Base DRE'!$L1:$L625,$C11,'Base DRE'!$K1:$K625,$H$2)} -> 0 | H11: {=_xlfn.SUMIFS('Base DRE'!$E1:$E625,'Base DRE'!$I1:$I625,H$7,'Base DRE'!$L1:$L625,$C11,'Base DRE'!$K1:$K625,$H$2)} -> 0 | J11: {=_xlfn.SUMIFS('Base DRE'!$E1:$E625,'Base DRE'!$I1:$I625,J$7,'Base DRE'!$L1:$L625,$C11,'Base DRE'!$K1:$K625,$H$2)} -> 0 | L11: {=_xlfn.SUMIFS('Base DRE'!$E1:$E625,'Base DRE'!$I1:$I625,L$7,'Base DRE'!$L1:$L625,$C11,'Base DRE'!$K1:$K625,$H$2)} -> 0 | N11: {=_xlfn.SUMIFS('Base DRE'!$E1:$E625,'Base DRE'!$I1:$I625,N$7,'Base DRE'!$L1:$L625,$C11,'Base DRE'!$K1:$K625,$H$2)} -> 0 | P11: {=_xlfn.SUMIFS('Base DRE'!$E1:$E625,'Base DRE'!$I1:$I625,P$7,'Base DRE'!$L1:$L625,$C11,'Base DRE'!$K1:$K625,$H$2)} -> 0 | R11: {=_xlfn.SUMIFS('Base DRE'!$E1:$E625,'Base DRE'!$I1:$I625,R$7,'Base DRE'!$L1:$L625,$C11,'Base DRE'!$K1:$K625,$H$2)} -> 0 | T11: {=_xlfn.SUMIFS('Base DRE'!$E1:$E625,'Base DRE'!$I1:$I625,T$7,'Base DRE'!$L1:$L625,$C11,'Base DRE'!$K1:$K625,$H$2)} -> 0 | V11: {=_xlfn.SUMIFS('Base DRE'!$E1:$E625,'Base DRE'!$I1:$I625,V$7,'Base DRE'!$L1:$L625,$C11,'Base DRE'!$K1:$K625,$H$2)} -> 0 | X11: {=_xlfn.SUMIFS('Base DRE'!$E1:$E625,'Base DRE'!$I1:$I625,X$7,'Base DRE'!$L1:$L625,$C11,'Base DRE'!$K1:$K625,$H$2)} -> 0 | Z11: {=_xlfn.SUMIFS('Base DRE'!$E1:$E625,'Base DRE'!$I1:$I625,Z$7,'Base DRE'!$L1:$L625,$C11,'Base DRE'!$K1:$K625,$H$2)} -> 0
C12: Receita de Aluguéis Recebidos | D12: {=_xlfn.SUMIFS('Base DRE'!$E1:$E625,'Base DRE'!$I1:$I625,D$7,'Base DRE'!$L1:$L625,$C12,'Base DRE'!$K1:$K625,$H$2)} -> 0 | F12: {=_xlfn.SUMIFS('Base DRE'!$E1:$E625,'Base DRE'!$I1:$I625,F$7,'Base DRE'!$L1:$L625,$C12,'Base DRE'!$K1:$K625,$H$2)} -> 0 | H12: {=_xlfn.SUMIFS('Base DRE'!$E1:$E625,'Base DRE'!$I1:$I625,H$7,'Base DRE'!$L1:$L625,$C12,'Base DRE'!$K1:$K625,$H$2)} -> 0 | J12: {=_xlfn.SUMIFS('Base DRE'!$E1:$E625,'Base DRE'!$I1:$I625,J$7,'Base DRE'!$L1:$L625,$C12,'Base DRE'!$K1:$K625,$H$2)} -> 0 | L12: {=_xlfn.SUMIFS('Base DRE'!$E1:$E625,'Base DRE'!$I1:$I625,L$7,'Base DRE'!$L1:$L625,$C12,'Base DRE'!$K1:$K625,$H$2)} -> 0 | N12: {=_xlfn.SUMIFS('Base DRE'!$E1:$E625,'Base DRE'!$I1:$I625,N$7,'Base DRE'!$L1:$L625,$C12,'Base DRE'!$K1:$K625,$H$2)} -> 0 | P12: {=_xlfn.SUMIFS('Base DRE'!$E1:$E625,'Base DRE'!$I1:$I625,P$7,'Base DRE'!$L1:$L625,$C12,'Base DRE'!$K1:$K625,$H$2)} -> 0 | R12: {=_xlfn.SUMIFS('Base DRE'!$E1:$E625,'Base DRE'!$I1:$I625,R$7,'Base DRE'!$L1:$L625,$C12,'Base DRE'!$K1:$K625,$H$2)} -> 0 | T12: {=_xlfn.SUMIFS('Base DRE'!$E1:$E625,'Base DRE'!$I1:$I625,T$7,'Base DRE'!$L1:$L625,$C12,'Base DRE'!$K1:$K625,$H$2)} -> 0 | V12: {=_xlfn.SUMIFS('Base DRE'!$E1:$E625,'Base DRE'!$I1:$I625,V$7,'Base DRE'!$L1:$L625,$C12,'Base DRE'!$K1:$K625,$H$2)} -> 0 | X12: {=_xlfn.SUMIFS('Base DRE'!$E1:$E625,'Base DRE'!$I1:$I625,X$7,'Base DRE'!$L1:$L625,$C12,'Base DRE'!$K1:$K625,$H$2)} -> 0 | Z12: {=_xlfn.SUMIFS('Base DRE'!$E1:$E625,'Base DRE'!$I1:$I625,Z$7,'Base DRE'!$L1:$L625,$C12,'Base DRE'!$K1:$K625,$H$2)} -> 0
C14: ( = ) Receita Bruta de Vendas | D14: {=D8} -> 0 | E14: {=_xlfn.IFERROR(D14/D$8,"")} | F14: {=F8} -> 0 | G14: {=_xlfn.IFERROR(F14/F$8,"")} | H14: {=H8} -> 0 | I14: {=_xlfn.IFERROR(H14/H$8,"")} | J14: {=J8} -> 0 | K14: {=_xlfn.IFERROR(J14/J$8,"")} | L14: {=L8} -> 0 | M14: {=_xlfn.IFERROR(L14/L$8,"")} | N14: {=N8} -> 0 | O14: {=_xlfn.IFERROR(N14/N$8,"")} | P14: {=P8} -> 0 | Q14: {=_xlfn.IFERROR(P14/P$8,"")} | R14: {=R8} -> 0 | S14: {=_xlfn.IFERROR(R14/R$8,"")} | T14: {=T8} -> 0 | U14: {=_xlfn.IFERROR(T14/T$8,"")} | V14: {=V8} -> 0 | W14: {=_xlfn.IFERROR(V14/V$8,"")} | X14: {=X8} -> 0 | Y14: {=_xlfn.IFERROR(X14/X$8,"")} | Z14: {=Z8} -> 0 | AA14: {=_xlfn.IFERROR(Z14/Z$8,"")}
B16: 2. | C16: ( - ) Deduções da Receita Bruta (Despesa Variável) | D16: {=D17} -> 0 | E16: {=_xlfn.IFERROR(D16/D$8,"")} | F16: {=F17} -> 0 | G16: {=_xlfn.IFERROR(F16/F$8,"")} | H16: {=H17} -> 0 | I16: {=_xlfn.IFERROR(H16/H$8,"")} | J16: {=J17} -> 0 | K16: {=_xlfn.IFERROR(J16/J$8,"")} | L16: {=L17} -> 0 | M16: {=_xlfn.IFERROR(L16/L$8,"")} | N16: {=N17} -> 0 | O16: {=_xlfn.IFERROR(N16/N$8,"")} | P16: {=P17} -> 0 | Q16: {=_xlfn.IFERROR(P16/P$8,"")} | R16: {=R17} -> 0 | S16: {=_xlfn.IFERROR(R16/R$8,"")} | T16: {=T17} -> 0 | U16: {=_xlfn.IFERROR(T16/T$8,"")} | V16: {=V17} -> 0 | W16: {=_xlfn.IFERROR(V16/V$8,"")} | X16: {=X17} -> 0 | Y16: {=_xlfn.IFERROR(X16/X$8,"")} | Z16: {=Z17} -> 0 | AA16: {=_xlfn.IFERROR(Z16/Z$8,"")}
C17: Dedições e impostos | D17: {=SUM(D18:D20)} -> 0 | E17: {=_xlfn.IFERROR(D17/D$8,"")} | F17: {=SUM(F18:F20)} -> 0 | G17: {=_xlfn.IFERROR(F17/F$8,"")} | H17: {=SUM(H18:H20)} -> 0 | I17: {=_xlfn.IFERROR(H17/H$8,"")} | J17: {=SUM(J18:J20)} -> 0 | K17: {=_xlfn.IFERROR(J17/J$8,"")} | L17: {=SUM(L18:L20)} -> 0 | M17: {=_xlfn.IFERROR(L17/L$8,"")} | N17: {=SUM(N18:N20)} -> 0 | O17: {=_xlfn.IFERROR(N17/N$8,"")} | P17: {=SUM(P18:P20)} -> 0 | Q17: {=_xlfn.IFERROR(P17/P$8,"")} | R17: {=SUM(R18:R20)} -> 0 | S17: {=_xlfn.IFERROR(R17/R$8,"")} | T17: {=SUM(T18:T20)} -> 0 | U17: {=_xlfn.IFERROR(T17/T$8,"")} | V17: {=SUM(V18:V20)} -> 0 | W17: {=_xlfn.IFERROR(V17/V$8,"")} | X17: {=SUM(X18:X20)} -> 0 | Y17: {=_xlfn.IFERROR(X17/X$8,"")} | Z17: {=SUM(Z18:Z20)} -> 0 | AA17: {=_xlfn.IFERROR(Z17/Z$8,"")}
B18: DESPESA | C18: Comissão de Vendas | D18: {=_xlfn.SUMIFS('Base DRE'!$E1:$E625,'Base DRE'!$I1:$I625,D$7,'Base DRE'!$L1:$L625,$C18,'Base DRE'!$K1:$K625,$H$2)} -> 0 | F18: {=_xlfn.SUMIFS('Base DRE'!$E1:$E625,'Base DRE'!$I1:$I625,F$7,'Base DRE'!$L1:$L625,$C18,'Base DRE'!$K1:$K625,$H$2)} -> 0 | H18: {=_xlfn.SUMIFS('Base DRE'!$E1:$E625,'Base DRE'!$I1:$I625,H$7,'Base DRE'!$L1:$L625,$C18,'Base DRE'!$K1:$K625,$H$2)} -> 0 | J18: {=_xlfn.SUMIFS('Base DRE'!$E1:$E625,'Base DRE'!$I1:$I625,J$7,'Base DRE'!$L1:$L625,$C18,'Base DRE'!$K1:$K625,$H$2)} -> 0 | L18: {=_xlfn.SUMIFS('Base DRE'!$E1:$E625,'Base DRE'!$I1:$I625,L$7,'Base DRE'!$L1:$L625,$C18,'Base DRE'!$K1:$K625,$H$2)} -> 0 | N18: {=_xlfn.SUMIFS('Base DRE'!$E1:$E625,'Base DRE'!$I1:$I625,N$7,'Base DRE'!$L1:$L625,$C18,'Base DRE'!$K1:$K625,$H$2)} -> 0 | P18: {=_xlfn.SUMIFS('Base DRE'!$E1:$E625,'Base DRE'!$I1:$I625,P$7,'Base DRE'!$L1:$L625,$C18,'Base DRE'!$K1:$K625,$H$2)} -> 0 | R18: {=_xlfn.SUMIFS('Base DRE'!$E1:$E625,'Base DRE'!$I1:$I625,R$7,'Base DRE'!$L1:$L625,$C18,'Base DRE'!$K1:$K625,$H$2)} -> 0 | T18: {=_xlfn.SUMIFS('Base DRE'!$E1:$E625,'Base DRE'!$I1:$I625,T$7,'Base DRE'!$L1:$L625,$C18,'Base DRE'!$K1:$K625,$H$2)} -> 0 | V18: {=_xlfn.SUMIFS('Base DRE'!$E1:$E625,'Base DRE'!$I1:$I625,V$7,'Base DRE'!$L1:$L625,$C18,'Base DRE'!$K1:$K625,$H$2)} -> 0 | X18: {=_xlfn.SUMIFS('Base DRE'!$E1:$E625,'Base DRE'!$I1:$I625,X$7,'Base DRE'!$L1:$L625,$C18,'Base DRE'!$K1:$K625,$H$2)} -> 0 | Z18: {=_xlfn.SUMIFS('Base DRE'!$E1:$E625,'Base DRE'!$I1:$I625,Z$7,'Base DRE'!$L1:$L625,$C18,'Base DRE'!$K1:$K625,$H$2)} -> 0
B19: DESPESA | C19: Impostos sobre vendas (ISS, ICMS, etc.) | D19: {=_xlfn.SUMIFS('Base DRE'!$E1:$E625,'Base DRE'!$I1:$I625,D$7,'Base DRE'!$L1:$L625,$C19,'Base DRE'!$K1:$K625,$H$2)} -> 0 | F19: {=_xlfn.SUMIFS('Base DRE'!$E1:$E625,'Base DRE'!$I1:$I625,F$7,'Base DRE'!$L1:$L625,$C19,'Base DRE'!$K1:$K625,$H$2)} -> 0 | H19: {=_xlfn.SUMIFS('Base DRE'!$E1:$E625,'Base DRE'!$I1:$I625,H$7,'Base DRE'!$L1:$L625,$C19,'Base DRE'!$K1:$K625,$H$2)} -> 0 | J19: {=_xlfn.SUMIFS('Base DRE'!$E1:$E625,'Base DRE'!$I1:$I625,J$7,'Base DRE'!$L1:$L625,$C19,'Base DRE'!$K1:$K625,$H$2)} -> 0 | L19: {=_xlfn.SUMIFS('Base DRE'!$E1:$E625,'Base DRE'!$I1:$I625,L$7,'Base DRE'!$L1:$L625,$C19,'Base DRE'!$K1:$K625,$H$2)} -> 0 | N19: {=_xlfn.SUMIFS('Base DRE'!$E1:$E625,'Base DRE'!$I1:$I625,N$7,'Base DRE'!$L1:$L625,$C19,'Base DRE'!$K1:$K625,$H$2)} -> 0 | P19: {=_xlfn.SUMIFS('Base DRE'!$E1:$E625,'Base DRE'!$I1:$I625,P$7,'Base DRE'!$L1:$L625,$C19,'Base DRE'!$K1:$K625,$H$2)} -> 0 | R19: {=_xlfn.SUMIFS('Base DRE'!$E1:$E625,'Base DRE'!$I1:$I625,R$7,'Base DRE'!$L1:$L625,$C19,'Base DRE'!$K1:$K625,$H$2)} -> 0 | T19: {=_xlfn.SUMIFS('Base DRE'!$E1:$E625,'Base DRE'!$I1:$I625,T$7,'Base DRE'!$L1:$L625,$C19,'Base DRE'!$K1:$K625,$H$2)} -> 0 | V19: {=_xlfn.SUMIFS('Base DRE'!$E1:$E625,'Base DRE'!$I1:$I625,V$7,'Base DRE'!$L1:$L625,$C19,'Base DRE'!$K1:$K625,$H$2)} -> 0 | X19: {=_xlfn.SUMIFS('Base DRE'!$E1:$E625,'Base DRE'!$I1:$I625,X$7,'Base DRE'!$L1:$L625,$C19,'Base DRE'!$K1:$K625,$H$2)} -> 0 | Z19: {=_xlfn.SUMIFS('Base DRE'!$E1:$E625,'Base DRE'!$I1:$I625,Z$7,'Base DRE'!$L1:$L625,$C19,'Base DRE'!$K1:$K625,$H$2)} -> 0
D20: {=_xlfn.SUMIFS('Base DRE'!$E1:$E625,'Base DRE'!$I1:$I625,D$7,'Base DRE'!$L1:$L625,$C20,'Base DRE'!$K1:$K625,$H$2)} -> 0 | F20: {=_xlfn.SUMIFS('Base DRE'!$E1:$E625,'Base DRE'!$I1:$I625,F$7,'Base DRE'!$L1:$L625,$C20,'Base DRE'!$K1:$K625,$H$2)} -> 0 | H20: {=_xlfn.SUMIFS('Base DRE'!$E1:$E625,'Base DRE'!$I1:$I625,H$7,'Base DRE'!$L1:$L625,$C20,'Base DRE'!$K1:$K625,$H$2)} -> 0 | J20: {=_xlfn.SUMIFS('Base DRE'!$E1:$E625,'Base DRE'!$I1:$I625,J$7,'Base DRE'!$L1:$L625,$C20,'Base DRE'!$K1:$K625,$H$2)} -> 0 | L20: {=_xlfn.SUMIFS('Base DRE'!$E1:$E625,'Base DRE'!$I1:$I625,L$7,'Base DRE'!$L1:$L625,$C20,'Base DRE'!$K1:$K625,$H$2)} -> 0 | N20: {=_xlfn.SUMIFS('Base DRE'!$E1:$E625,'Base DRE'!$I1:$I625,N$7,'Base DRE'!$L1:$L625,$C20,'Base DRE'!$K1:$K625,$H$2)} -> 0 | P20: {=_xlfn.SUMIFS('Base DRE'!$E1:$E625,'Base DRE'!$I1:$I625,P$7,'Base DRE'!$L1:$L625,$C20,'Base DRE'!$K1:$K625,$H$2)} -> 0 | R20: {=_xlfn.SUMIFS('Base DRE'!$E1:$E625,'Base DRE'!$I1:$I625,R$7,'Base DRE'!$L1:$L625,$C20,'Base DRE'!$K1:$K625,$H$2)} -> 0 | T20: {=_xlfn.SUMIFS('Base DRE'!$E1:$E625,'Base DRE'!$I1:$I625,T$7,'Base DRE'!$L1:$L625,$C20,'Base DRE'!$K1:$K625,$H$2)} -> 0 | V20: {=_xlfn.SUMIFS('Base DRE'!$E1:$E625,'Base DRE'!$I1:$I625,V$7,'Base DRE'!$L1:$L625,$C20,'Base DRE'!$K1:$K625,$H$2)} -> 0 | X20: {=_xlfn.SUMIFS('Base DRE'!$E1:$E625,'Base DRE'!$I1:$I625,X$7,'Base DRE'!$L1:$L625,$C20,'Base DRE'!$K1:$K625,$H$2)} -> 0 | Z20: {=_xlfn.SUMIFS('Base DRE'!$E1:$E625,'Base DRE'!$I1:$I625,Z$7,'Base DRE'!$L1:$L625,$C20,'Base DRE'!$K1:$K625,$H$2)} -> 0
C22: ( = ) Receita Líquida de Vendas | D22: {=D14+D16} -> 0 | E22: {=_xlfn.IFERROR(D22/D$8,"")} | F22: {=F14+F16} -> 0 | G22: {=_xlfn.IFERROR(F22/F$8,"")} | H22: {=H14+H16} -> 0 | I22: {=_xlfn.IFERROR(H22/H$8,"")} | J22: {=J14+J16} -> 0 | K22: {=_xlfn.IFERROR(J22/J$8,"")} | L22: {=L14+L16} -> 0 | M22: {=_xlfn.IFERROR(L22/L$8,"")} | N22: {=N14+N16} -> 0 | O22: {=_xlfn.IFERROR(N22/N$8,"")} | P22: {=P14+P16} -> 0 | Q22: {=_xlfn.IFERROR(P22/P$8,"")} | R22: {=R14+R16} -> 0 | S22: {=_xlfn.IFERROR(R22/R$8,"")} | T22: {=T14+T16} -> 0 | U22: {=_xlfn.IFERROR(T22/T$8,"")} | V22: {=V14+V16} -> 0 | W22: {=_xlfn.IFERROR(V22/V$8,"")} | X22: {=X14+X16} -> 0 | Y22: {=_xlfn.IFERROR(X22/X$8,"")} | Z22: {=Z14+Z16} -> 0 | AA22: {=_xlfn.IFERROR(Z22/Z$8,"")}
B24: 3. | C24: ( - ) Custos Operacionais (Custos Variáveis) | D24: {=D25} -> 0 | E24: {=_xlfn.IFERROR(D24/D$8,"")} | F24: {=F25} -> 0 | G24: {=_xlfn.IFERROR(F24/F$8,"")} | H24: {=H25} -> 0 | I24: {=_xlfn.IFERROR(H24/H$8,"")} | J24: {=J25} -> 0 | K24: {=_xlfn.IFERROR(J24/J$8,"")} | L24: {=L25} -> 0 | M24: {=_xlfn.IFERROR(L24/L$8,"")} | N24: {=N25} -> 0 | O24: {=_xlfn.IFERROR(N24/N$8,"")} | P24: {=P25} -> 0 | Q24: {=_xlfn.IFERROR(P24/P$8,"")} | R24: {=R25} -> 0 | S24: {=_xlfn.IFERROR(R24/R$8,"")} | T24: {=T25} -> 0 | U24: {=_xlfn.IFERROR(T24/T$8,"")} | V24: {=V25} -> 0 | W24: {=_xlfn.IFERROR(V24/V$8,"")} | X24: {=X25} -> 0 | Y24: {=_xlfn.IFERROR(X24/X$8,"")} | Z24: {=Z25} -> 0 | AA24: {=_xlfn.IFERROR(Z24/Z$8,"")}
C25: Custos Variáveis | D25: {=SUM(D26:D29)} -> 0 | E25: {=_xlfn.IFERROR(D25/D$8,"")} | F25: {=SUM(F26:F29)} -> 0 | G25: {=_xlfn.IFERROR(F25/F$8,"")} | H25: {=SUM(H26:H29)} -> 0 | I25: {=_xlfn.IFERROR(H25/H$8,"")} | J25: {=SUM(J26:J29)} -> 0 | K25: {=_xlfn.IFERROR(J25/J$8,"")} | L25: {=SUM(L26:L29)} -> 0 | M25: {=_xlfn.IFERROR(L25/L$8,"")} | N25: {=SUM(N26:N29)} -> 0 | O25: {=_xlfn.IFERROR(N25/N$8,"")} | P25: {=SUM(P26:P29)} -> 0 | Q25: {=_xlfn.IFERROR(P25/P$8,"")} | R25: {=SUM(R26:R29)} -> 0 | S25: {=_xlfn.IFERROR(R25/R$8,"")} | T25: {=SUM(T26:T29)} -> 0 | U25: {=_xlfn.IFERROR(T25/T$8,"")} | V25: {=SUM(V26:V29)} -> 0 | W25: {=_xlfn.IFERROR(V25/V$8,"")} | X25: {=SUM(X26:X29)} -> 0 | Y25: {=_xlfn.IFERROR(X25/X$8,"")} | Z25: {=SUM(Z26:Z29)} -> 0 | AA25: {=_xlfn.IFERROR(Z25/Z$8,"")}
B26: DESPESA | C26: Custo de Mercadoria Vendida (CMV) | D26: {=_xlfn.SUMIFS('Base DRE'!$E1:$E625,'Base DRE'!$I1:$I625,D$7,'Base DRE'!$L1:$L625,$C26,'Base DRE'!$K1:$K625,$H$2)} -> 0 | F26: {=_xlfn.SUMIFS('Base DRE'!$E1:$E625,'Base DRE'!$I1:$I625,F$7,'Base DRE'!$L1:$L625,$C26,'Base DRE'!$K1:$K625,$H$2)} -> 0 | H26: {=_xlfn.SUMIFS('Base DRE'!$E1:$E625,'Base DRE'!$I1:$I625,H$7,'Base DRE'!$L1:$L625,$C26,'Base DRE'!$K1:$K625,$H$2)} -> 0 | J26: {=_xlfn.SUMIFS('Base DRE'!$E1:$E625,'Base DRE'!$I1:$I625,J$7,'Base DRE'!$L1:$L625,$C26,'Base DRE'!$K1:$K625,$H$2)} -> 0 | L26: {=_xlfn.SUMIFS('Base DRE'!$E1:$E625,'Base DRE'!$I1:$I625,L$7,'Base DRE'!$L1:$L625,$C26,'Base DRE'!$K1:$K625,$H$2)} -> 0 | N26: {=_xlfn.SUMIFS('Base DRE'!$E1:$E625,'Base DRE'!$I1:$I625,N$7,'Base DRE'!$L1:$L625,$C26,'Base DRE'!$K1:$K625,$H$2)} -> 0 | P26: {=_xlfn.SUMIFS('Base DRE'!$E1:$E625,'Base DRE'!$I1:$I625,P$7,'Base DRE'!$L1:$L625,$C26,'Base DRE'!$K1:$K625,$H$2)} -> 0 | R26: {=_xlfn.SUMIFS('Base DRE'!$E1:$E625,'Base DRE'!$I1:$I625,R$7,'Base DRE'!$L1:$L625,$C26,'Base DRE'!$K1:$K625,$H$2)} -> 0 | T26: {=_xlfn.SUMIFS('Base DRE'!$E1:$E625,'Base DRE'!$I1:$I625,T$7,'Base DRE'!$L1:$L625,$C26,'Base DRE'!$K1:$K625,$H$2)} -> 0 | V26: {=_xlfn.SUMIFS('Base DRE'!$E1:$E625,'Base DRE'!$I1:$I625,V$7,'Base DRE'!$L1:$L625,$C26,'Base DRE'!$K1:$K625,$H$2)} -> 0 | X26: {=_xlfn.SUMIFS('Base DRE'!$E1:$E625,'Base DRE'!$I1:$I625,X$7,'Base DRE'!$L1:$L625,$C26,'Base DRE'!$K1:$K625,$H$2)} -> 0 | Z26: {=_xlfn.SUMIFS('Base DRE'!$E1:$E625,'Base DRE'!$I1:$I625,Z$7,'Base DRE'!$L1:$L625,$C26,'Base DRE'!$K1:$K625,$H$2)} -> 0
B27: DESPESA | C27: Matéria-prima Consumida | D27: {=_xlfn.SUMIFS('Base DRE'!$E1:$E625,'Base DRE'!$I1:$I625,D$7,'Base DRE'!$L1:$L625,$C27,'Base DRE'!$K1:$K625,$H$2)} -> 0 | F27: {=_xlfn.SUMIFS('Base DRE'!$E1:$E625,'Base DRE'!$I1:$I625,F$7,'Base DRE'!$L1:$L625,$C27,'Base DRE'!$K1:$K625,$H$2)} -> 0 | H27: {=_xlfn.SUMIFS('Base DRE'!$E1:$E625,'Base DRE'!$I1:$I625,H$7,'Base DRE'!$L1:$L625,$C27,'Base DRE'!$K1:$K625,$H$2)} -> 0 | J27: {=_xlfn.SUMIFS('Base DRE'!$E1:$E625,'Base DRE'!$I1:$I625,J$7,'Base DRE'!$L1:$L625,$C27,'Base DRE'!$K1:$K625,$H$2)} -> 0 | L27: {=_xlfn.SUMIFS('Base DRE'!$E1:$E625,'Base DRE'!$I1:$I625,L$7,'Base DRE'!$L1:$L625,$C27,'Base DRE'!$K1:$K625,$H$2)} -> 0 | N27: {=_xlfn.SUMIFS('Base DRE'!$E1:$E625,'Base DRE'!$I1:$I625,N$7,'Base DRE'!$L1:$L625,$C27,'Base DRE'!$K1:$K625,$H$2)} -> 0 | P27: {=_xlfn.SUMIFS('Base DRE'!$E1:$E625,'Base DRE'!$I1:$I625,P$7,'Base DRE'!$L1:$L625,$C27,'Base DRE'!$K1:$K625,$H$2)} -> 0 | R27: {=_xlfn.SUMIFS('Base DRE'!$E1:$E625,'Base DRE'!$I1:$I625,R$7,'Base DRE'!$L1:$L625,$C27,'Base DRE'!$K1:$K625,$H$2)} -> 0 | T27: {=_xlfn.SUMIFS('Base DRE'!$E1:$E625,'Base DRE'!$I1:$I625,T$7,'Base DRE'!$L1:$L625,$C27,'Base DRE'!$K1:$K625,$H$2)} -> 0 | V27: {=_xlfn.SUMIFS('Base DRE'!$E1:$E625,'Base DRE'!$I1:$I625,V$7,'Base DRE'!$L1:$L625,$C27,'Base DRE'!$K1:$K625,$H$2)} -> 0 | X27: {=_xlfn.SUMIFS('Base DRE'!$E1:$E625,'Base DRE'!$I1:$I625,X$7,'Base DRE'!$L1:$L625,$C27,'Base DRE'!$K1:$K625,$H$2)} -> 0 | Z27: {=_xlfn.SUMIFS('Base DRE'!$E1:$E625,'Base DRE'!$I1:$I625,Z$7,'Base DRE'!$L1:$L625,$C27,'Base DRE'!$K1:$K625,$H$2)} -> 0
B28: DESPESA | C28: Frete sobre vendas | D28: {=_xlfn.SUMIFS('Base DRE'!$E1:$E625,'Base DRE'!$I1:$I625,D$7,'Base DRE'!$L1:$L625,$C28,'Base DRE'!$K1:$K625,$H$2)} -> 0 | F28: {=_xlfn.SUMIFS('Base DRE'!$E1:$E625,'Base DRE'!$I1:$I625,F$7,'Base DRE'!$L1:$L625,$C28,'Base DRE'!$K1:$K625,$H$2)} -> 0 | H28: {=_xlfn.SUMIFS('Base DRE'!$E1:$E625,'Base DRE'!$I1:$I625,H$7,'Base DRE'!$L1:$L625,$C28,'Base DRE'!$K1:$K625,$H$2)} -> 0 | J28: {=_xlfn.SUMIFS('Base DRE'!$E1:$E625,'Base DRE'!$I1:$I625,J$7,'Base DRE'!$L1:$L625,$C28,'Base DRE'!$K1:$K625,$H$2)} -> 0 | L28: {=_xlfn.SUMIFS('Base DRE'!$E1:$E625,'Base DRE'!$I1:$I625,L$7,'Base DRE'!$L1:$L625,$C28,'Base DRE'!$K1:$K625,$H$2)} -> 0 | N28: {=_xlfn.SUMIFS('Base DRE'!$E1:$E625,'Base DRE'!$I1:$I625,N$7,'Base DRE'!$L1:$L625,$C28,'Base DRE'!$K1:$K625,$H$2)} -> 0 | P28: {=_xlfn.SUMIFS('Base DRE'!$E1:$E625,'Base DRE'!$I1:$I625,P$7,'Base DRE'!$L1:$L625,$C28,'Base DRE'!$K1:$K625,$H$2)} -> 0 | R28: {=_xlfn.SUMIFS('Base DRE'!$E1:$E625,'Base DRE'!$I1:$I625,R$7,'Base DRE'!$L1:$L625,$C28,'Base DRE'!$K1:$K625,$H$2)} -> 0 | T28: {=_xlfn.SUMIFS('Base DRE'!$E1:$E625,'Base DRE'!$I1:$I625,T$7,'Base DRE'!$L1:$L625,$C28,'Base DRE'!$K1:$K625,$H$2)} -> 0 | V28: {=_xlfn.SUMIFS('Base DRE'!$E1:$E625,'Base DRE'!$I1:$I625,V$7,'Base DRE'!$L1:$L625,$C28,'Base DRE'!$K1:$K625,$H$2)} -> 0 | X28: {=_xlfn.SUMIFS('Base DRE'!$E1:$E625,'Base DRE'!$I1:$I625,X$7,'Base DRE'!$L1:$L625,$C28,'Base DRE'!$K1:$K625,$H$2)} -> 0 | Z28: {=_xlfn.SUMIFS('Base DRE'!$E1:$E625,'Base DRE'!$I1:$I625,Z$7,'Base DRE'!$L1:$L625,$C28,'Base DRE'!$K1:$K625,$H$2)} -> 0
B29: DESPESA
C31: ( = ) Lucro Bruto | D31: {=D22+D24} -> 0 | E31: {=_xlfn.IFERROR(D31/D$8,"")} | F31: {=F22+F24} -> 0 | G31: {=_xlfn.IFERROR(F31/F$8,"")} | H31: {=H22+H24} -> 0 | I31: {=_xlfn.IFERROR(H31/H$8,"")} | J31: {=J22+J24} -> 0 | K31: {=_xlfn.IFERROR(J31/J$8,"")} | L31: {=L22+L24} -> 0 | M31: {=_xlfn.IFERROR(L31/L$8,"")} | N31: {=N22+N24} -> 0 | O31: {=_xlfn.IFERROR(N31/N$8,"")} | P31: {=P22+P24} -> 0 | Q31: {=_xlfn.IFERROR(P31/P$8,"")} | R31: {=R22+R24} -> 0 | S31: {=_xlfn.IFERROR(R31/R$8,"")} | T31: {=T22+T24} -> 0 | U31: {=_xlfn.IFERROR(T31/T$8,"")} | V31: {=V22+V24} -> 0 | W31: {=_xlfn.IFERROR(V31/V$8,"")} | X31: {=X22+X24} -> 0 | Y31: {=_xlfn.IFERROR(X31/X$8,"")} | Z31: {=Z22+Z24} -> 0 | AA31: {=_xlfn.IFERROR(Z31/Z$8,"")}
N32: {=N33/O31}
B33: 4. | C33: ( - ) Despesas Operacionais (Custos Fixos) | D33: {=SUM(D34,D39,D52)} -> 0 | E33: {=_xlfn.IFERROR(D33/D$8,"")} | F33: {=SUM(F34,F39,F52)} -> 0 | G33: {=_xlfn.IFERROR(F33/F$8,"")} | H33: {=SUM(H34,H39,H52)} -> 0 | I33: {=_xlfn.IFERROR(H33/H$8,"")} | J33: {=SUM(J34,J39,J52)} -> 0 | K33: {=_xlfn.IFERROR(J33/J$8,"")} | L33: {=SUM(L34,L39,L52)} -> 0 | M33: {=_xlfn.IFERROR(L33/L$8,"")} | N33: {=SUM(N34,N39,N52)} -> 0 | O33: {=_xlfn.IFERROR(N33/N$8,"")} | P33: {=SUM(P34,P39,P52)} -> 0 | Q33: {=_xlfn.IFERROR(P33/P$8,"")} | R33: {=SUM(R34,R39,R52)} -> 0 | S33: {=_xlfn.IFERROR(R33/R$8,"")} | T33: {=SUM(T34,T39,T52)} -> 0 | U33: {=_xlfn.IFERROR(T33/T$8,"")} | V33: {=SUM(V34,V39,V52)} -> 0 | W33: {=_xlfn.IFERROR(V33/V$8,"")} | X33: {=SUM(X34,X39,X52)} -> 0 | Y33: {=_xlfn.IFERROR(X33/X$8,"")} | Z33: {=SUM(Z34,Z39,Z52)} -> 0 | AA33: {=_xlfn.IFERROR(Z33/Z$8,"")}
B34: 4.1 | C34: Custos Fixos - Despesa Com Pessoal | D34: {=SUM(D35:D37)} -> 0 | E34: {=_xlfn.IFERROR(D34/D$8,"")} | F34: {=SUM(F35:F37)} -> 0 | G34: {=_xlfn.IFERROR(F34/F$8,"")} | H34: {=SUM(H35:H37)} -> 0 | I34: {=_xlfn.IFERROR(H34/H$8,"")} | J34: {=SUM(J35:J37)} -> 0 | K34: {=_xlfn.IFERROR(J34/J$8,"")} | L34: {=SUM(L35:L37)} -> 0 | M34: {=_xlfn.IFERROR(L34/L$8,"")} | N34: {=SUM(N35:N37)} -> 0 | O34: {=_xlfn.IFERROR(N34/N$8,"")} | P34: {=SUM(P35:P37)} -> 0 | Q34: {=_xlfn.IFERROR(P34/P$8,"")} | R34: {=SUM(R35:R37)} -> 0 | S34: {=_xlfn.IFERROR(R34/R$8,"")} | T34: {=SUM(T35:T37)} -> 0 | U34: {=_xlfn.IFERROR(T34/T$8,"")} | V34: {=SUM(V35:V37)} -> 0 | W34: {=_xlfn.IFERROR(V34/V$8,"")} | X34: {=SUM(X35:X37)} -> 0 | Y34: {=_xlfn.IFERROR(X34/X$8,"")} | Z34: {=SUM(Z35:Z37)} -> 0 | AA34: {=_xlfn.IFERROR(Z34/Z$8,"")}
C35: Salários e Encargos Administrativos | D35: {=_xlfn.SUMIFS('Base DRE'!$E1:$E625,'Base DRE'!$I1:$I625,D$7,'Base DRE'!$L1:$L625,$C35,'Base DRE'!$K1:$K625,$H$2)} -> 0 | F35: {=_xlfn.SUMIFS('Base DRE'!$E1:$E625,'Base DRE'!$I1:$I625,F$7,'Base DRE'!$L1:$L625,$C35,'Base DRE'!$K1:$K625,$H$2)} -> 0 | H35: {=_xlfn.SUMIFS('Base DRE'!$E1:$E625,'Base DRE'!$I1:$I625,H$7,'Base DRE'!$L1:$L625,$C35,'Base DRE'!$K1:$K625,$H$2)} -> 0 | J35: {=_xlfn.SUMIFS('Base DRE'!$E1:$E625,'Base DRE'!$I1:$I625,J$7,'Base DRE'!$L1:$L625,$C35,'Base DRE'!$K1:$K625,$H$2)} -> 0 | L35: {=_xlfn.SUMIFS('Base DRE'!$E1:$E625,'Base DRE'!$I1:$I625,L$7,'Base DRE'!$L1:$L625,$C35,'Base DRE'!$K1:$K625,$H$2)} -> 0 | N35: {=_xlfn.SUMIFS('Base DRE'!$E1:$E625,'Base DRE'!$I1:$I625,N$7,'Base DRE'!$L1:$L625,$C35,'Base DRE'!$K1:$K625,$H$2)} -> 0 | P35: {=_xlfn.SUMIFS('Base DRE'!$E1:$E625,'Base DRE'!$I1:$I625,P$7,'Base DRE'!$L1:$L625,$C35,'Base DRE'!$K1:$K625,$H$2)} -> 0 | R35: {=_xlfn.SUMIFS('Base DRE'!$E1:$E625,'Base DRE'!$I1:$I625,R$7,'Base DRE'!$L1:$L625,$C35,'Base DRE'!$K1:$K625,$H$2)} -> 0 | T35: {=_xlfn.SUMIFS('Base DRE'!$E1:$E625,'Base DRE'!$I1:$I625,T$7,'Base DRE'!$L1:$L625,$C35,'Base DRE'!$K1:$K625,$H$2)} -> 0 | V35: {=_xlfn.SUMIFS('Base DRE'!$E1:$E625,'Base DRE'!$I1:$I625,V$7,'Base DRE'!$L1:$L625,$C35,'Base DRE'!$K1:$K625,$H$2)} -> 0 | X35: {=_xlfn.SUMIFS('Base DRE'!$E1:$E625,'Base DRE'!$I1:$I625,X$7,'Base DRE'!$L1:$L625,$C35,'Base DRE'!$K1:$K625,$H$2)} -> 0 | Z35: {=_xlfn.SUMIFS('Base DRE'!$E1:$E625,'Base DRE'!$I1:$I625,Z$7,'Base DRE'!$L1:$L625,$C35,'Base DRE'!$K1:$K625,$H$2)} -> 0
C36: Salários e Encargos do Comercial | D36: {=_xlfn.SUMIFS('Base DRE'!$E1:$E625,'Base DRE'!$I1:$I625,D$7,'Base DRE'!$L1:$L625,$C36,'Base DRE'!$K1:$K625,$H$2)} -> 0 | F36: {=_xlfn.SUMIFS('Base DRE'!$E1:$E625,'Base DRE'!$I1:$I625,F$7,'Base DRE'!$L1:$L625,$C36,'Base DRE'!$K1:$K625,$H$2)} -> 0 | H36: {=_xlfn.SUMIFS('Base DRE'!$E1:$E625,'Base DRE'!$I1:$I625,H$7,'Base DRE'!$L1:$L625,$C36,'Base DRE'!$K1:$K625,$H$2)} -> 0 | J36: {=_xlfn.SUMIFS('Base DRE'!$E1:$E625,'Base DRE'!$I1:$I625,J$7,'Base DRE'!$L1:$L625,$C36,'Base DRE'!$K1:$K625,$H$2)} -> 0 | L36: {=_xlfn.SUMIFS('Base DRE'!$E1:$E625,'Base DRE'!$I1:$I625,L$7,'Base DRE'!$L1:$L625,$C36,'Base DRE'!$K1:$K625,$H$2)} -> 0 | N36: {=_xlfn.SUMIFS('Base DRE'!$E1:$E625,'Base DRE'!$I1:$I625,N$7,'Base DRE'!$L1:$L625,$C36,'Base DRE'!$K1:$K625,$H$2)} -> 0 | P36: {=_xlfn.SUMIFS('Base DRE'!$E1:$E625,'Base DRE'!$I1:$I625,P$7,'Base DRE'!$L1:$L625,$C36,'Base DRE'!$K1:$K625,$H$2)} -> 0 | R36: {=_xlfn.SUMIFS('Base DRE'!$E1:$E625,'Base DRE'!$I1:$I625,R$7,'Base DRE'!$L1:$L625,$C36,'Base DRE'!$K1:$K625,$H$2)} -> 0 | T36: {=_xlfn.SUMIFS('Base DRE'!$E1:$E625,'Base DRE'!$I1:$I625,T$7,'Base DRE'!$L1:$L625,$C36,'Base DRE'!$K1:$K625,$H$2)} -> 0 | V36: {=_xlfn.SUMIFS('Base DRE'!$E1:$E625,'Base DRE'!$I1:$I625,V$7,'Base DRE'!$L1:$L625,$C36,'Base DRE'!$K1:$K625,$H$2)} -> 0 | X36: {=_xlfn.SUMIFS('Base DRE'!$E1:$E625,'Base DRE'!$I1:$I625,X$7,'Base DRE'!$L1:$L625,$C36,'Base DRE'!$K1:$K625,$H$2)} -> 0 | Z36: {=_xlfn.SUMIFS('Base DRE'!$E1:$E625,'Base DRE'!$I1:$I625,Z$7,'Base DRE'!$L1:$L625,$C36,'Base DRE'!$K1:$K625,$H$2)} -> 0
C37: Provisões (13º, férias, etc.) | D37: {=_xlfn.SUMIFS('Base DRE'!$E1:$E625,'Base DRE'!$I1:$I625,D$7,'Base DRE'!$L1:$L625,$C37,'Base DRE'!$K1:$K625,$H$2)} -> 0 | F37: {=_xlfn.SUMIFS('Base DRE'!$E1:$E625,'Base DRE'!$I1:$I625,F$7,'Base DRE'!$L1:$L625,$C37,'Base DRE'!$K1:$K625,$H$2)} -> 0 | H37: {=_xlfn.SUMIFS('Base DRE'!$E1:$E625,'Base DRE'!$I1:$I625,H$7,'Base DRE'!$L1:$L625,$C37,'Base DRE'!$K1:$K625,$H$2)} -> 0 | J37: {=_xlfn.SUMIFS('Base DRE'!$E1:$E625,'Base DRE'!$I1:$I625,J$7,'Base DRE'!$L1:$L625,$C37,'Base DRE'!$K1:$K625,$H$2)} -> 0 | L37: {=_xlfn.SUMIFS('Base DRE'!$E1:$E625,'Base DRE'!$I1:$I625,L$7,'Base DRE'!$L1:$L625,$C37,'Base DRE'!$K1:$K625,$H$2)} -> 0 | N37: {=_xlfn.SUMIFS('Base DRE'!$E1:$E625,'Base DRE'!$I1:$I625,N$7,'Base DRE'!$L1:$L625,$C37,'Base DRE'!$K1:$K625,$H$2)} -> 0 | P37: {=_xlfn.SUMIFS('Base DRE'!$E1:$E625,'Base DRE'!$I1:$I625,P$7,'Base DRE'!$L1:$L625,$C37,'Base DRE'!$K1:$K625,$H$2)} -> 0 | R37: {=_xlfn.SUMIFS('Base DRE'!$E1:$E625,'Base DRE'!$I1:$I625,R$7,'Base DRE'!$L1:$L625,$C37,'Base DRE'!$K1:$K625,$H$2)} -> 0 | T37: {=_xlfn.SUMIFS('Base DRE'!$E1:$E625,'Base DRE'!$I1:$I625,T$7,'Base DRE'!$L1:$L625,$C37,'Base DRE'!$K1:$K625,$H$2)} -> 0 | V37: {=_xlfn.SUMIFS('Base DRE'!$E1:$E625,'Base DRE'!$I1:$I625,V$7,'Base DRE'!$L1:$L625,$C37,'Base DRE'!$K1:$K625,$H$2)} -> 0 | X37: {=_xlfn.SUMIFS('Base DRE'!$E1:$E625,'Base DRE'!$I1:$I625,X$7,'Base DRE'!$L1:$L625,$C37,'Base DRE'!$K1:$K625,$H$2)} -> 0 | Z37: {=_xlfn.SUMIFS('Base DRE'!$E1:$E625,'Base DRE'!$I1:$I625,Z$7,'Base DRE'!$L1:$L625,$C37,'Base DRE'!$K1:$K625,$H$2)} -> 0
B39: 4.2 | C39: Custos Fixos - Despesa Administrativa | D39: {=SUM(D40:D51)} -> 0 | E39: {=_xlfn.IFERROR(D39/D$8,"")} | F39: {=SUM(F40:F54)} -> 0 | G39: {=_xlfn.IFERROR(F39/F$8,"")} | H39: {=SUM(H40:H54)} -> 0 | I39: {=_xlfn.IFERROR(H39/H$8,"")} | J39: {=SUM(J40:J54)} -> 0 | K39: {=_xlfn.IFERROR(J39/J$8,"")} | L39: {=SUM(L40:L54)} -> 0 | M39: {=_xlfn.IFERROR(L39/L$8,"")} | N39: {=SUM(N40:N54)} -> 0 | O39: {=_xlfn.IFERROR(N39/N$8,"")} | P39: {=SUM(P40:P54)} -> 0 | Q39: {=_xlfn.IFERROR(P39/P$8,"")} | R39: {=SUM(R40:R54)} -> 0 | S39: {=_xlfn.IFERROR(R39/R$8,"")} | T39: {=SUM(T40:T54)} -> 0 | U39: {=_xlfn.IFERROR(T39/T$8,"")} | V39: {=SUM(V40:V54)} -> 0 | W39: {=_xlfn.IFERROR(V39/V$8,"")} | X39: {=SUM(X40:X54)} -> 0 | Y39: {=_xlfn.IFERROR(X39/X$8,"")} | Z39: {=SUM(Z40:Z54)} -> 0 | AA39: {=_xlfn.IFERROR(Z39/Z$8,"")}
B40: DESPESA | C40: Aluguel | D40: {=_xlfn.SUMIFS('Base DRE'!$E1:$E625,'Base DRE'!$I1:$I625,D$7,'Base DRE'!$L1:$L625,$C40,'Base DRE'!$K1:$K625,$H$2)} -> 0 | F40: {=_xlfn.SUMIFS('Base DRE'!$E1:$E625,'Base DRE'!$I1:$I625,F$7,'Base DRE'!$L1:$L625,$C40,'Base DRE'!$K1:$K625,$H$2)} -> 0 | H40: {=_xlfn.SUMIFS('Base DRE'!$E1:$E625,'Base DRE'!$I1:$I625,H$7,'Base DRE'!$L1:$L625,$C40,'Base DRE'!$K1:$K625,$H$2)} -> 0 | J40: {=_xlfn.SUMIFS('Base DRE'!$E1:$E625,'Base DRE'!$I1:$I625,J$7,'Base DRE'!$L1:$L625,$C40,'Base DRE'!$K1:$K625,$H$2)} -> 0 | L40: {=_xlfn.SUMIFS('Base DRE'!$E1:$E625,'Base DRE'!$I1:$I625,L$7,'Base DRE'!$L1:$L625,$C40,'Base DRE'!$K1:$K625,$H$2)} -> 0 | N40: {=_xlfn.SUMIFS('Base DRE'!$E1:$E625,'Base DRE'!$I1:$I625,N$7,'Base DRE'!$L1:$L625,$C40,'Base DRE'!$K1:$K625,$H$2)} -> 0 | P40: {=_xlfn.SUMIFS('Base DRE'!$E1:$E625,'Base DRE'!$I1:$I625,P$7,'Base DRE'!$L1:$L625,$C40,'Base DRE'!$K1:$K625,$H$2)} -> 0 | R40: {=_xlfn.SUMIFS('Base DRE'!$E1:$E625,'Base DRE'!$I1:$I625,R$7,'Base DRE'!$L1:$L625,$C40,'Base DRE'!$K1:$K625,$H$2)} -> 0 | T40: {=_xlfn.SUMIFS('Base DRE'!$E1:$E625,'Base DRE'!$I1:$I625,T$7,'Base DRE'!$L1:$L625,$C40,'Base DRE'!$K1:$K625,$H$2)} -> 0 | V40: {=_xlfn.SUMIFS('Base DRE'!$E1:$E625,'Base DRE'!$I1:$I625,V$7,'Base DRE'!$L1:$L625,$C40,'Base DRE'!$K1:$K625,$H$2)} -> 0 | X40: {=_xlfn.SUMIFS('Base DRE'!$E1:$E625,'Base DRE'!$I1:$I625,X$7,'Base DRE'!$L1:$L625,$C40,'Base DRE'!$K1:$K625,$H$2)} -> 0 | Z40: {=_xlfn.SUMIFS('Base DRE'!$E1:$E625,'Base DRE'!$I1:$I625,Z$7,'Base DRE'!$L1:$L625,$C40,'Base DRE'!$K1:$K625,$H$2)} -> 0
C41: Contabilidade | D41: {=_xlfn.SUMIFS('Base DRE'!$E1:$E625,'Base DRE'!$I1:$I625,D$7,'Base DRE'!$L1:$L625,$C41,'Base DRE'!$K1:$K625,$H$2)} -> 0 | F41: {=_xlfn.SUMIFS('Base DRE'!$E1:$E625,'Base DRE'!$I1:$I625,F$7,'Base DRE'!$L1:$L625,$C41,'Base DRE'!$K1:$K625,$H$2)} -> 0 | H41: {=_xlfn.SUMIFS('Base DRE'!$E1:$E625,'Base DRE'!$I1:$I625,H$7,'Base DRE'!$L1:$L625,$C41,'Base DRE'!$K1:$K625,$H$2)} -> 0 | J41: {=_xlfn.SUMIFS('Base DRE'!$E1:$E625,'Base DRE'!$I1:$I625,J$7,'Base DRE'!$L1:$L625,$C41,'Base DRE'!$K1:$K625,$H$2)} -> 0 | L41: {=_xlfn.SUMIFS('Base DRE'!$E1:$E625,'Base DRE'!$I1:$I625,L$7,'Base DRE'!$L1:$L625,$C41,'Base DRE'!$K1:$K625,$H$2)} -> 0 | N41: {=_xlfn.SUMIFS('Base DRE'!$E1:$E625,'Base DRE'!$I1:$I625,N$7,'Base DRE'!$L1:$L625,$C41,'Base DRE'!$K1:$K625,$H$2)} -> 0 | P41: {=_xlfn.SUMIFS('Base DRE'!$E1:$E625,'Base DRE'!$I1:$I625,P$7,'Base DRE'!$L1:$L625,$C41,'Base DRE'!$K1:$K625,$H$2)} -> 0 | R41: {=_xlfn.SUMIFS('Base DRE'!$E1:$E625,'Base DRE'!$I1:$I625,R$7,'Base DRE'!$L1:$L625,$C41,'Base DRE'!$K1:$K625,$H$2)} -> 0 | T41: {=_xlfn.SUMIFS('Base DRE'!$E1:$E625,'Base DRE'!$I1:$I625,T$7,'Base DRE'!$L1:$L625,$C41,'Base DRE'!$K1:$K625,$H$2)} -> 0 | V41: {=_xlfn.SUMIFS('Base DRE'!$E1:$E625,'Base DRE'!$I1:$I625,V$7,'Base DRE'!$L1:$L625,$C41,'Base DRE'!$K1:$K625,$H$2)} -> 0 | X41: {=_xlfn.SUMIFS('Base DRE'!$E1:$E625,'Base DRE'!$I1:$I625,X$7,'Base DRE'!$L1:$L625,$C41,'Base DRE'!$K1:$K625,$H$2)} -> 0 | Z41: {=_xlfn.SUMIFS('Base DRE'!$E1:$E625,'Base DRE'!$I1:$I625,Z$7,'Base DRE'!$L1:$L625,$C41,'Base DRE'!$K1:$K625,$H$2)} -> 0
C42: Consultorias | D42: {=_xlfn.SUMIFS('Base DRE'!$E1:$E625,'Base DRE'!$I1:$I625,D$7,'Base DRE'!$L1:$L625,$C42,'Base DRE'!$K1:$K625,$H$2)} -> 0 | F42: {=_xlfn.SUMIFS('Base DRE'!$E1:$E625,'Base DRE'!$I1:$I625,F$7,'Base DRE'!$L1:$L625,$C42,'Base DRE'!$K1:$K625,$H$2)} -> 0 | H42: {=_xlfn.SUMIFS('Base DRE'!$E1:$E625,'Base DRE'!$I1:$I625,H$7,'Base DRE'!$L1:$L625,$C42,'Base DRE'!$K1:$K625,$H$2)} -> 0 | J42: {=_xlfn.SUMIFS('Base DRE'!$E1:$E625,'Base DRE'!$I1:$I625,J$7,'Base DRE'!$L1:$L625,$C42,'Base DRE'!$K1:$K625,$H$2)} -> 0 | L42: {=_xlfn.SUMIFS('Base DRE'!$E1:$E625,'Base DRE'!$I1:$I625,L$7,'Base DRE'!$L1:$L625,$C42,'Base DRE'!$K1:$K625,$H$2)} -> 0 | N42: {=_xlfn.SUMIFS('Base DRE'!$E1:$E625,'Base DRE'!$I1:$I625,N$7,'Base DRE'!$L1:$L625,$C42,'Base DRE'!$K1:$K625,$H$2)} -> 0 | P42: {=_xlfn.SUMIFS('Base DRE'!$E1:$E625,'Base DRE'!$I1:$I625,P$7,'Base DRE'!$L1:$L625,$C42,'Base DRE'!$K1:$K625,$H$2)} -> 0 | R42: {=_xlfn.SUMIFS('Base DRE'!$E1:$E625,'Base DRE'!$I1:$I625,R$7,'Base DRE'!$L1:$L625,$C42,'Base DRE'!$K1:$K625,$H$2)} -> 0 | T42: {=_xlfn.SUMIFS('Base DRE'!$E1:$E625,'Base DRE'!$I1:$I625,T$7,'Base DRE'!$L1:$L625,$C42,'Base DRE'!$K1:$K625,$H$2)} -> 0 | V42: {=_xlfn.SUMIFS('Base DRE'!$E1:$E625,'Base DRE'!$I1:$I625,V$7,'Base DRE'!$L1:$L625,$C42,'Base DRE'!$K1:$K625,$H$2)} -> 0 | X42: {=_xlfn.SUMIFS('Base DRE'!$E1:$E625,'Base DRE'!$I1:$I625,X$7,'Base DRE'!$L1:$L625,$C42,'Base DRE'!$K1:$K625,$H$2)} -> 0 | Z42: {=_xlfn.SUMIFS('Base DRE'!$E1:$E625,'Base DRE'!$I1:$I625,Z$7,'Base DRE'!$L1:$L625,$C42,'Base DRE'!$K1:$K625,$H$2)} -> 0
C43: Licenças e Softwares e TI | D43: {=_xlfn.SUMIFS('Base DRE'!$E1:$E625,'Base DRE'!$I1:$I625,D$7,'Base DRE'!$L1:$L625,$C43,'Base DRE'!$K1:$K625,$H$2)} -> 0 | F43: {=_xlfn.SUMIFS('Base DRE'!$E1:$E625,'Base DRE'!$I1:$I625,F$7,'Base DRE'!$L1:$L625,$C43,'Base DRE'!$K1:$K625,$H$2)} -> 0 | H43: {=_xlfn.SUMIFS('Base DRE'!$E1:$E625,'Base DRE'!$I1:$I625,H$7,'Base DRE'!$L1:$L625,$C43,'Base DRE'!$K1:$K625,$H$2)} -> 0 | J43: {=_xlfn.SUMIFS('Base DRE'!$E1:$E625,'Base DRE'!$I1:$I625,J$7,'Base DRE'!$L1:$L625,$C43,'Base DRE'!$K1:$K625,$H$2)} -> 0 | L43: {=_xlfn.SUMIFS('Base DRE'!$E1:$E625,'Base DRE'!$I1:$I625,L$7,'Base DRE'!$L1:$L625,$C43,'Base DRE'!$K1:$K625,$H$2)} -> 0 | N43: {=_xlfn.SUMIFS('Base DRE'!$E1:$E625,'Base DRE'!$I1:$I625,N$7,'Base DRE'!$L1:$L625,$C43,'Base DRE'!$K1:$K625,$H$2)} -> 0 | P43: {=_xlfn.SUMIFS('Base DRE'!$E1:$E625,'Base DRE'!$I1:$I625,P$7,'Base DRE'!$L1:$L625,$C43,'Base DRE'!$K1:$K625,$H$2)} -> 0 | R43: {=_xlfn.SUMIFS('Base DRE'!$E1:$E625,'Base DRE'!$I1:$I625,R$7,'Base DRE'!$L1:$L625,$C43,'Base DRE'!$K1:$K625,$H$2)} -> 0 | T43: {=_xlfn.SUMIFS('Base DRE'!$E1:$E625,'Base DRE'!$I1:$I625,T$7,'Base DRE'!$L1:$L625,$C43,'Base DRE'!$K1:$K625,$H$2)} -> 0 | V43: {=_xlfn.SUMIFS('Base DRE'!$E1:$E625,'Base DRE'!$I1:$I625,V$7,'Base DRE'!$L1:$L625,$C43,'Base DRE'!$K1:$K625,$H$2)} -> 0 | X43: {=_xlfn.SUMIFS('Base DRE'!$E1:$E625,'Base DRE'!$I1:$I625,X$7,'Base DRE'!$L1:$L625,$C43,'Base DRE'!$K1:$K625,$H$2)} -> 0 | Z43: {=_xlfn.SUMIFS('Base DRE'!$E1:$E625,'Base DRE'!$I1:$I625,Z$7,'Base DRE'!$L1:$L625,$C43,'Base DRE'!$K1:$K625,$H$2)} -> 0
C44: Marketing e Publicidade | D44: {=_xlfn.SUMIFS('Base DRE'!$E1:$E625,'Base DRE'!$I1:$I625,D$7,'Base DRE'!$L1:$L625,$C44,'Base DRE'!$K1:$K625,$H$2)} -> 0 | F44: {=_xlfn.SUMIFS('Base DRE'!$E1:$E625,'Base DRE'!$I1:$I625,F$7,'Base DRE'!$L1:$L625,$C44,'Base DRE'!$K1:$K625,$H$2)} -> 0 | H44: {=_xlfn.SUMIFS('Base DRE'!$E1:$E625,'Base DRE'!$I1:$I625,H$7,'Base DRE'!$L1:$L625,$C44,'Base DRE'!$K1:$K625,$H$2)} -> 0 | J44: {=_xlfn.SUMIFS('Base DRE'!$E1:$E625,'Base DRE'!$I1:$I625,J$7,'Base DRE'!$L1:$L625,$C44,'Base DRE'!$K1:$K625,$H$2)} -> 0 | L44: {=_xlfn.SUMIFS('Base DRE'!$E1:$E625,'Base DRE'!$I1:$I625,L$7,'Base DRE'!$L1:$L625,$C44,'Base DRE'!$K1:$K625,$H$2)} -> 0 | N44: {=_xlfn.SUMIFS('Base DRE'!$E1:$E625,'Base DRE'!$I1:$I625,N$7,'Base DRE'!$L1:$L625,$C44,'Base DRE'!$K1:$K625,$H$2)} -> 0 | P44: {=_xlfn.SUMIFS('Base DRE'!$E1:$E625,'Base DRE'!$I1:$I625,P$7,'Base DRE'!$L1:$L625,$C44,'Base DRE'!$K1:$K625,$H$2)} -> 0 | R44: {=_xlfn.SUMIFS('Base DRE'!$E1:$E625,'Base DRE'!$I1:$I625,R$7,'Base DRE'!$L1:$L625,$C44,'Base DRE'!$K1:$K625,$H$2)} -> 0 | T44: {=_xlfn.SUMIFS('Base DRE'!$E1:$E625,'Base DRE'!$I1:$I625,T$7,'Base DRE'!$L1:$L625,$C44,'Base DRE'!$K1:$K625,$H$2)} -> 0 | V44: {=_xlfn.SUMIFS('Base DRE'!$E1:$E625,'Base DRE'!$I1:$I625,V$7,'Base DRE'!$L1:$L625,$C44,'Base DRE'!$K1:$K625,$H$2)} -> 0 | X44: {=_xlfn.SUMIFS('Base DRE'!$E1:$E625,'Base DRE'!$I1:$I625,X$7,'Base DRE'!$L1:$L625,$C44,'Base DRE'!$K1:$K625,$H$2)} -> 0 | Z44: {=_xlfn.SUMIFS('Base DRE'!$E1:$E625,'Base DRE'!$I1:$I625,Z$7,'Base DRE'!$L1:$L625,$C44,'Base DRE'!$K1:$K625,$H$2)} -> 0
C45: Ferramentas de CRM ou automação | D45: {=_xlfn.SUMIFS('Base DRE'!$E1:$E625,'Base DRE'!$I1:$I625,D$7,'Base DRE'!$L1:$L625,$C45,'Base DRE'!$K1:$K625,$H$2)} -> 0 | F45: {=_xlfn.SUMIFS('Base DRE'!$E1:$E625,'Base DRE'!$I1:$I625,F$7,'Base DRE'!$L1:$L625,$C45,'Base DRE'!$K1:$K625,$H$2)} -> 0 | H45: {=_xlfn.SUMIFS('Base DRE'!$E1:$E625,'Base DRE'!$I1:$I625,H$7,'Base DRE'!$L1:$L625,$C45,'Base DRE'!$K1:$K625,$H$2)} -> 0 | J45: {=_xlfn.SUMIFS('Base DRE'!$E1:$E625,'Base DRE'!$I1:$I625,J$7,'Base DRE'!$L1:$L625,$C45,'Base DRE'!$K1:$K625,$H$2)} -> 0 | L45: {=_xlfn.SUMIFS('Base DRE'!$E1:$E625,'Base DRE'!$I1:$I625,L$7,'Base DRE'!$L1:$L625,$C45,'Base DRE'!$K1:$K625,$H$2)} -> 0 | N45: {=_xlfn.SUMIFS('Base DRE'!$E1:$E625,'Base DRE'!$I1:$I625,N$7,'Base DRE'!$L1:$L625,$C45,'Base DRE'!$K1:$K625,$H$2)} -> 0 | P45: {=_xlfn.SUMIFS('Base DRE'!$E1:$E625,'Base DRE'!$I1:$I625,P$7,'Base DRE'!$L1:$L625,$C45,'Base DRE'!$K1:$K625,$H$2)} -> 0 | R45: {=_xlfn.SUMIFS('Base DRE'!$E1:$E625,'Base DRE'!$I1:$I625,R$7,'Base DRE'!$L1:$L625,$C45,'Base DRE'!$K1:$K625,$H$2)} -> 0 | T45: {=_xlfn.SUMIFS('Base DRE'!$E1:$E625,'Base DRE'!$I1:$I625,T$7,'Base DRE'!$L1:$L625,$C45,'Base DRE'!$K1:$K625,$H$2)} -> 0 | V45: {=_xlfn.SUMIFS('Base DRE'!$E1:$E625,'Base DRE'!$I1:$I625,V$7,'Base DRE'!$L1:$L625,$C45,'Base DRE'!$K1:$K625,$H$2)} -> 0 | X45: {=_xlfn.SUMIFS('Base DRE'!$E1:$E625,'Base DRE'!$I1:$I625,X$7,'Base DRE'!$L1:$L625,$C45,'Base DRE'!$K1:$K625,$H$2)} -> 0 | Z45: {=_xlfn.SUMIFS('Base DRE'!$E1:$E625,'Base DRE'!$I1:$I625,Z$7,'Base DRE'!$L1:$L625,$C45,'Base DRE'!$K1:$K625,$H$2)} -> 0
C46: Viagens e Refeições Comerciais | D46: {=_xlfn.SUMIFS('Base DRE'!$E1:$E625,'Base DRE'!$I1:$I625,D$7,'Base DRE'!$L1:$L625,$C46,'Base DRE'!$K1:$K625,$H$2)} -> 0 | F46: {=_xlfn.SUMIFS('Base DRE'!$E1:$E625,'Base DRE'!$I1:$I625,F$7,'Base DRE'!$L1:$L625,$C46,'Base DRE'!$K1:$K625,$H$2)} -> 0 | H46: {=_xlfn.SUMIFS('Base DRE'!$E1:$E625,'Base DRE'!$I1:$I625,H$7,'Base DRE'!$L1:$L625,$C46,'Base DRE'!$K1:$K625,$H$2)} -> 0 | J46: {=_xlfn.SUMIFS('Base DRE'!$E1:$E625,'Base DRE'!$I1:$I625,J$7,'Base DRE'!$L1:$L625,$C46,'Base DRE'!$K1:$K625,$H$2)} -> 0 | L46: {=_xlfn.SUMIFS('Base DRE'!$E1:$E625,'Base DRE'!$I1:$I625,L$7,'Base DRE'!$L1:$L625,$C46,'Base DRE'!$K1:$K625,$H$2)} -> 0 | N46: {=_xlfn.SUMIFS('Base DRE'!$E1:$E625,'Base DRE'!$I1:$I625,N$7,'Base DRE'!$L1:$L625,$C46,'Base DRE'!$K1:$K625,$H$2)} -> 0 | P46: {=_xlfn.SUMIFS('Base DRE'!$E1:$E625,'Base DRE'!$I1:$I625,P$7,'Base DRE'!$L1:$L625,$C46,'Base DRE'!$K1:$K625,$H$2)} -> 0 | R46: {=_xlfn.SUMIFS('Base DRE'!$E1:$E625,'Base DRE'!$I1:$I625,R$7,'Base DRE'!$L1:$L625,$C46,'Base DRE'!$K1:$K625,$H$2)} -> 0 | T46: {=_xlfn.SUMIFS('Base DRE'!$E1:$E625,'Base DRE'!$I1:$I625,T$7,'Base DRE'!$L1:$L625,$C46,'Base DRE'!$K1:$K625,$H$2)} -> 0 | V46: {=_xlfn.SUMIFS('Base DRE'!$E1:$E625,'Base DRE'!$I1:$I625,V$7,'Base DRE'!$L1:$L625,$C46,'Base DRE'!$K1:$K625,$H$2)} -> 0 | X46: {=_xlfn.SUMIFS('Base DRE'!$E1:$E625,'Base DRE'!$I1:$I625,X$7,'Base DRE'!$L1:$L625,$C46,'Base DRE'!$K1:$K625,$H$2)} -> 0 | Z46: {=_xlfn.SUMIFS('Base DRE'!$E1:$E625,'Base DRE'!$I1:$I625,Z$7,'Base DRE'!$L1:$L625,$C46,'Base DRE'!$K1:$K625,$H$2)} -> 0
C47: Energia Elétrica | D47: {=_xlfn.SUMIFS('Base DRE'!$E1:$E625,'Base DRE'!$I1:$I625,D$7,'Base DRE'!$L1:$L625,$C47,'Base DRE'!$K1:$K625,$H$2)} -> 0 | F47: {=_xlfn.SUMIFS('Base DRE'!$E1:$E625,'Base DRE'!$I1:$I625,F$7,'Base DRE'!$L1:$L625,$C47,'Base DRE'!$K1:$K625,$H$2)} -> 0 | H47: {=_xlfn.SUMIFS('Base DRE'!$E1:$E625,'Base DRE'!$I1:$I625,H$7,'Base DRE'!$L1:$L625,$C47,'Base DRE'!$K1:$K625,$H$2)} -> 0 | J47: {=_xlfn.SUMIFS('Base DRE'!$E1:$E625,'Base DRE'!$I1:$I625,J$7,'Base DRE'!$L1:$L625,$C47,'Base DRE'!$K1:$K625,$H$2)} -> 0 | L47: {=_xlfn.SUMIFS('Base DRE'!$E1:$E625,'Base DRE'!$I1:$I625,L$7,'Base DRE'!$L1:$L625,$C47,'Base DRE'!$K1:$K625,$H$2)} -> 0 | N47: {=_xlfn.SUMIFS('Base DRE'!$E1:$E625,'Base DRE'!$I1:$I625,N$7,'Base DRE'!$L1:$L625,$C47,'Base DRE'!$K1:$K625,$H$2)} -> 0 | P47: {=_xlfn.SUMIFS('Base DRE'!$E1:$E625,'Base DRE'!$I1:$I625,P$7,'Base DRE'!$L1:$L625,$C47,'Base DRE'!$K1:$K625,$H$2)} -> 0 | R47: {=_xlfn.SUMIFS('Base DRE'!$E1:$E625,'Base DRE'!$I1:$I625,R$7,'Base DRE'!$L1:$L625,$C47,'Base DRE'!$K1:$K625,$H$2)} -> 0 | T47: {=_xlfn.SUMIFS('Base DRE'!$E1:$E625,'Base DRE'!$I1:$I625,T$7,'Base DRE'!$L1:$L625,$C47,'Base DRE'!$K1:$K625,$H$2)} -> 0 | V47: {=_xlfn.SUMIFS('Base DRE'!$E1:$E625,'Base DRE'!$I1:$I625,V$7,'Base DRE'!$L1:$L625,$C47,'Base DRE'!$K1:$K625,$H$2)} -> 0 | X47: {=_xlfn.SUMIFS('Base DRE'!$E1:$E625,'Base DRE'!$I1:$I625,X$7,'Base DRE'!$L1:$L625,$C47,'Base DRE'!$K1:$K625,$H$2)} -> 0 | Z47: {=_xlfn.SUMIFS('Base DRE'!$E1:$E625,'Base DRE'!$I1:$I625,Z$7,'Base DRE'!$L1:$L625,$C47,'Base DRE'!$K1:$K625,$H$2)} -> 0
C48: Água | D48: {=_xlfn.SUMIFS('Base DRE'!$E1:$E625,'Base DRE'!$I1:$I625,D$7,'Base DRE'!$L1:$L625,$C48,'Base DRE'!$K1:$K625,$H$2)} -> 0 | F48: {=_xlfn.SUMIFS('Base DRE'!$E1:$E625,'Base DRE'!$I1:$I625,F$7,'Base DRE'!$L1:$L625,$C48,'Base DRE'!$K1:$K625,$H$2)} -> 0 | H48: {=_xlfn.SUMIFS('Base DRE'!$E1:$E625,'Base DRE'!$I1:$I625,H$7,'Base DRE'!$L1:$L625,$C48,'Base DRE'!$K1:$K625,$H$2)} -> 0 | J48: {=_xlfn.SUMIFS('Base DRE'!$E1:$E625,'Base DRE'!$I1:$I625,J$7,'Base DRE'!$L1:$L625,$C48,'Base DRE'!$K1:$K625,$H$2)} -> 0 | L48: {=_xlfn.SUMIFS('Base DRE'!$E1:$E625,'Base DRE'!$I1:$I625,L$7,'Base DRE'!$L1:$L625,$C48,'Base DRE'!$K1:$K625,$H$2)} -> 0 | N48: {=_xlfn.SUMIFS('Base DRE'!$E1:$E625,'Base DRE'!$I1:$I625,N$7,'Base DRE'!$L1:$L625,$C48,'Base DRE'!$K1:$K625,$H$2)} -> 0 | P48: {=_xlfn.SUMIFS('Base DRE'!$E1:$E625,'Base DRE'!$I1:$I625,P$7,'Base DRE'!$L1:$L625,$C48,'Base DRE'!$K1:$K625,$H$2)} -> 0 | R48: {=_xlfn.SUMIFS('Base DRE'!$E1:$E625,'Base DRE'!$I1:$I625,R$7,'Base DRE'!$L1:$L625,$C48,'Base DRE'!$K1:$K625,$H$2)} -> 0 | T48: {=_xlfn.SUMIFS('Base DRE'!$E1:$E625,'Base DRE'!$I1:$I625,T$7,'Base DRE'!$L1:$L625,$C48,'Base DRE'!$K1:$K625,$H$2)} -> 0 | V48: {=_xlfn.SUMIFS('Base DRE'!$E1:$E625,'Base DRE'!$I1:$I625,V$7,'Base DRE'!$L1:$L625,$C48,'Base DRE'!$K1:$K625,$H$2)} -> 0 | X48: {=_xlfn.SUMIFS('Base DRE'!$E1:$E625,'Base DRE'!$I1:$I625,X$7,'Base DRE'!$L1:$L625,$C48,'Base DRE'!$K1:$K625,$H$2)} -> 0 | Z48: {=_xlfn.SUMIFS('Base DRE'!$E1:$E625,'Base DRE'!$I1:$I625,Z$7,'Base DRE'!$L1:$L625,$C48,'Base DRE'!$K1:$K625,$H$2)} -> 0
C49: Internet e Telefonia | D49: {=_xlfn.SUMIFS('Base DRE'!$E1:$E625,'Base DRE'!$I1:$I625,D$7,'Base DRE'!$L1:$L625,$C49,'Base DRE'!$K1:$K625,$H$2)} -> 0 | F49: {=_xlfn.SUMIFS('Base DRE'!$E1:$E625,'Base DRE'!$I1:$I625,F$7,'Base DRE'!$L1:$L625,$C49,'Base DRE'!$K1:$K625,$H$2)} -> 0 | H49: {=_xlfn.SUMIFS('Base DRE'!$E1:$E625,'Base DRE'!$I1:$I625,H$7,'Base DRE'!$L1:$L625,$C49,'Base DRE'!$K1:$K625,$H$2)} -> 0 | J49: {=_xlfn.SUMIFS('Base DRE'!$E1:$E625,'Base DRE'!$I1:$I625,J$7,'Base DRE'!$L1:$L625,$C49,'Base DRE'!$K1:$K625,$H$2)} -> 0 | L49: {=_xlfn.SUMIFS('Base DRE'!$E1:$E625,'Base DRE'!$I1:$I625,L$7,'Base DRE'!$L1:$L625,$C49,'Base DRE'!$K1:$K625,$H$2)} -> 0 | N49: {=_xlfn.SUMIFS('Base DRE'!$E1:$E625,'Base DRE'!$I1:$I625,N$7,'Base DRE'!$L1:$L625,$C49,'Base DRE'!$K1:$K625,$H$2)} -> 0 | P49: {=_xlfn.SUMIFS('Base DRE'!$E1:$E625,'Base DRE'!$I1:$I625,P$7,'Base DRE'!$L1:$L625,$C49,'Base DRE'!$K1:$K625,$H$2)} -> 0 | R49: {=_xlfn.SUMIFS('Base DRE'!$E1:$E625,'Base DRE'!$I1:$I625,R$7,'Base DRE'!$L1:$L625,$C49,'Base DRE'!$K1:$K625,$H$2)} -> 0 | T49: {=_xlfn.SUMIFS('Base DRE'!$E1:$E625,'Base DRE'!$I1:$I625,T$7,'Base DRE'!$L1:$L625,$C49,'Base DRE'!$K1:$K625,$H$2)} -> 0 | V49: {=_xlfn.SUMIFS('Base DRE'!$E1:$E625,'Base DRE'!$I1:$I625,V$7,'Base DRE'!$L1:$L625,$C49,'Base DRE'!$K1:$K625,$H$2)} -> 0 | X49: {=_xlfn.SUMIFS('Base DRE'!$E1:$E625,'Base DRE'!$I1:$I625,X$7,'Base DRE'!$L1:$L625,$C49,'Base DRE'!$K1:$K625,$H$2)} -> 0 | Z49: {=_xlfn.SUMIFS('Base DRE'!$E1:$E625,'Base DRE'!$I1:$I625,Z$7,'Base DRE'!$L1:$L625,$C49,'Base DRE'!$K1:$K625,$H$2)} -> 0
...

Sheet Base DRE
E2: *
E4: {=IF(E2="*","TODOS",E2)} -> TODOS
E5: {=SUBTOTAL(9,E6:E619)} -> 0
B6: Data | C6: Descrição | D6: Documento | E6: Valor (R$) | F6: Saldo (R$) | G6: Banco | H6: Tipo Conta | I6: Mês | J6: Tipo | K6: Centro de Custo | L6: CATEGORIA | M6: TIPO | N6: COD | P6: CATEGORIA | Q6: TIPO | R6: COD | T6: CENTRO DE CUSTO | Z6: Lançamentos | AA6: Categorias
M7: {=_xlfn.IFERROR(VLOOKUP(L7,P1:R625,2,0),"")} | N7: {=_xlfn.IFERROR(VLOOKUP(L7,P1:R625,3,0),"")} | P7: Receita de Vendas - Produtos | Q7: Receita | R7: 1 | T7: Pessoal | Z7: DEBITO CONVENIOS 02558157000162 VIVO | AA7: Internet e Telefonia
M8: {=_xlfn.IFERROR(VLOOKUP(L8,P1:R625,2,0),"")} | N8: {=_xlfn.IFERROR(VLOOKUP(L8,P1:R625,3,0),"")} | P8: Receita de Vendas - Serviços | Q8: Receita | R8: 1 | T8: Empresa | Z8: LIQUIDACAO BOLETO 01703365000145 ESPERANTO COMER | AA8: Lançamentos a Identificar
M9: {=_xlfn.IFERROR(VLOOKUP(L9,P1:R625,2,0),"")} | N9: {=_xlfn.IFERROR(VLOOKUP(L9,P1:R625,3,0),"")} | P9: Receita de Aluguéis Recebidos | Q9: Receita | R9: 1 | Z9: LIQUIDACAO BOLETO 22037446000123 HYGIBRAS COMERC | AA9: Lançamentos a Identificar
M10: {=_xlfn.IFERROR(VLOOKUP(L10,P1:R625,2,0),"")} | N10: {=_xlfn.IFERROR(VLOOKUP(L10,P1:R625,3,0),"")} | P10: Receita Financeira | Q10: Receita | R10: 5.2 | Z10: LIQUIDACAO BOLETO 00489050000184 JJGC INDUSTRIA | AA10: Lançamentos a Identificar
M11: {=_xlfn.IFERROR(VLOOKUP(L11,P1:R625,2,0),"")} | N11: {=_xlfn.IFERROR(VLOOKUP(L11,P1:R625,3,0),"")} | P11: Outras Receitas Operacionais | Q11: Receita | R11: 6.1 | Z11: RECEBIMENTO PIX 06299336854 LUCIA DE FATIMA COST | AA11: Receita de Vendas - Serviços
M12: {=_xlfn.IFERROR(VLOOKUP(L12,P1:R625,2,0),"")} | N12: {=_xlfn.IFERROR(VLOOKUP(L12,P1:R625,3,0),"")} | P12: Custo de Mercadoria Vendida (CMV) | Q12: Custo Variável | R12: 3 | Z12: TARIFA COM R LIQUIDACAO | AA12: Tarifas Bancárias
M13: {=_xlfn.IFERROR(VLOOKUP(L13,P1:R625,2,0),"")} | N13: {=_xlfn.IFERROR(VLOOKUP(L13,P1:R625,3,0),"")} | P13: Matéria-prima Consumida | Q13: Custo Variável | R13: 3 | Z13: SUB CR VISA | EVOLUSERVI | 0001-26 | AA13: Receita de Vendas - Produtos
M14: {=_xlfn.IFERROR(VLOOKUP(L14,P1:R625,2,0),"")} | N14: {=_xlfn.IFERROR(VLOOKUP(L14,P1:R625,3,0),"")} | P14: Comissão de Vendas | Q14: Custo Variável | R14: 2 | Z14: SUB CR MASTER | EVOLUSERVI | 0001-26 | AA14: Receita de Vendas - Produtos
M15: {=_xlfn.IFERROR(VLOOKUP(L15,P1:R625,2,0),"")} | N15: {=_xlfn.IFERROR(VLOOKUP(L15,P1:R625,3,0),"")} | P15: Frete sobre vendas | Q15: Custo Variável | R15: 3 | Z15: SUB DB MASTER | SUMUP | 0001-26 | AA15: Receita de Vendas - Produtos
M16: {=_xlfn.IFERROR(VLOOKUP(L16,P1:R625,2,0),"")} | N16: {=_xlfn.IFERROR(VLOOKUP(L16,P1:R625,3,0),"")} | P16: Impostos sobre vendas (ISS, ICMS, etc.) | Q16: Custo Variável | R16: 2 | T16: * | Z16: TED 19540550000121 ASAAS GESTAO FINANCEIRA S.A. | AA16: Receita de Vendas - Serviços
M17: {=_xlfn.IFERROR(VLOOKUP(L17,P1:R625,2,0),"")} | N17: {=_xlfn.IFERROR(VLOOKUP(L17,P1:R625,3,0),"")} | P17: Salários e Encargos Administrativos | Q17: Despesa Administrativa | R17: 4.1 | Z17: SEGURO PRESTAMISTA | AA17: Lançamentos a Identificar
M18: {=_xlfn.IFERROR(VLOOKUP(L18,P1:R625,2,0),"")} | N18: {=_xlfn.IFERROR(VLOOKUP(L18,P1:R625,3,0),"")} | P18: Aluguel | Q18: Despesa Administrativa | R18: 4.2 | Z18: LIQ.COBRANCA SIMPLES | AA18: Outras Receitas Operacionais
M19: {=_xlfn.IFERROR(VLOOKUP(L19,P1:R625,2,0),"")} | N19: {=_xlfn.IFERROR(VLOOKUP(L19,P1:R625,3,0),"")} | P19: Contabilidade | Q19: Despesa Administrativa | R19: 4.2 | Z19: PAGAMENTO PIX 11369419000131 GELCOM | AA19: Lançamentos a Identificar
M20: {=_xlfn.IFERROR(VLOOKUP(L20,P1:R625,2,0),"")} | N20: {=_xlfn.IFERROR(VLOOKUP(L20,P1:R625,3,0),"")} | P20: Consultorias | Q20: Despesa Administrativa | R20: 4.2 | Z20: PAGAMENTO PIX 44466916861 Izadora Toloti Da Silv | AA20: Salários e Encargos Administrativos
M21: {=_xlfn.IFERROR(VLOOKUP(L21,P1:R625,2,0),"")} | N21: {=_xlfn.IFERROR(VLOOKUP(L21,P1:R625,3,0),"")} | P21: Licenças e Softwares e TI | Q21: Despesa Administrativa | R21: 4.2 | Z21: PAGAMENTO PIX 45950682807 Larissa Franco Amaro | AA21: Salários e Encargos Administrativos
M22: {=_xlfn.IFERROR(VLOOKUP(L22,P1:R625,2,0),"")} | N22: {=_xlfn.IFERROR(VLOOKUP(L22,P1:R625,3,0),"")} | P22: Salários e Encargos do Comercial | Q22: Despesa Comercial | R22: 4.1 | Z22: PAGAMENTO PIX 42439634875 Nathalia Cristina Tave | AA22: Salários e Encargos Administrativos
M23: {=_xlfn.IFERROR(VLOOKUP(L23,P1:R625,2,0),"")} | N23: {=_xlfn.IFERROR(VLOOKUP(L23,P1:R625,3,0),"")} | P23: Marketing e Publicidade | Q23: Despesa Comercial | R23: 4.2 | Z23: PAGAMENTO PIX 38814883831 FABIANA GARCIA | AA23: Salários e Encargos Administrativos
M24: {=_xlfn.IFERROR(VLOOKUP(L24,P1:R625,2,0),"")} | N24: {=_xlfn.IFERROR(VLOOKUP(L24,P1:R625,3,0),"")} | P24: Ferramentas de CRM ou automação | Q24: Despesa Comercial | R24: 4.2 | Z24: PAGAMENTO PIX 41305135000142 TRIANGULO ENGENHARI | AA24: Manutenção de Equipamentos
M25: {=_xlfn.IFERROR(VLOOKUP(L25,P1:R625,2,0),"")} | N25: {=_xlfn.IFERROR(VLOOKUP(L25,P1:R625,3,0),"")} | P25: Viagens e Refeições Comerciais | Q25: Despesa Comercial | R25: 4.2 | Z25: PAGAMENTO PIX 20018692826 ADEMIR JOSE CARNEIRO | AA25: Salários e Encargos Administrativos
M26: {=_xlfn.IFERROR(VLOOKUP(L26,P1:R625,2,0),"")} | N26: {=_xlfn.IFERROR(VLOOKUP(L26,P1:R625,3,0),"")} | P26: Energia Elétrica | Q26: Despesa Operacional | R26: 4.2 | Z26: PAGAMENTO PIX 02639887831 EUNICE GOMES DOS SANTO | AA26: Salários e Encargos Administrativos
M27: {=_xlfn.IFERROR(VLOOKUP(L27,P1:R625,2,0),"")} | N27: {=_xlfn.IFERROR(VLOOKUP(L27,P1:R625,3,0),"")} | P27: Água | Q27: Despesa Operacional | R27: 4.2 | Z27: CUSTAS DE PROTESTO | AA27: Multas e Encargos
M28: {=_xlfn.IFERROR(VLOOKUP(L28,P1:R625,2,0),"")} | N28: {=_xlfn.IFERROR(VLOOKUP(L28,P1:R625,3,0),"")} | P28: Internet e Telefonia | Q28: Despesa Operacional | R28: 4.2 | Z28: TARIFA DE PROTESTO | AA28: Tarifas Bancárias
M29: {=_xlfn.IFERROR(VLOOKUP(L29,P1:R625,2,0),"")} | N29: {=_xlfn.IFERROR(VLOOKUP(L29,P1:R625,3,0),"")} | P29: Manutenção de Equipamentos | Q29: Despesa Operacional | R29: 4.2 | Z29: SUB DB ELO | EVOLUSERVI | 0001-26 | AA29: Receita de Vendas - Produtos
M30: {=_xlfn.IFERROR(VLOOKUP(L30,P1:R625,2,0),"")} | N30: {=_xlfn.IFERROR(VLOOKUP(L30,P1:R625,3,0),"")} | P30: Juros sobre Empréstimos | Q30: Despesa Financeira | R30: 5.1 | Z30: PAGAMENTO PIX 53238195883 Thayná Bachiego Cossol | AA30: Salários e Encargos Administrativos
M31: {=_xlfn.IFERROR(VLOOKUP(L31,P1:R625,2,0),"")} | N31: {=_xlfn.IFERROR(VLOOKUP(L31,P1:R625,3,0),"")} | P31: Tarifas Bancárias | Q31: Despesa Financeira | R31: 5.1 | Z31: PAGAMENTO PIX 50316590843 TAMARA GABRIELE DOMING | AA31: Salários e Encargos Administrativos
M32: {=_xlfn.IFERROR(VLOOKUP(L32,P1:R625,2,0),"")} | N32: {=_xlfn.IFERROR(VLOOKUP(L32,P1:R625,3,0),"")} | P32: Multas e Encargos | Q32: Despesa Financeira | R32: 5.1 | Z32: PAGAMENTO PIX 38052340829 ANA CLAUDIA DE OLIVEIR | AA32: Salários e Encargos Administrativos
M33: {=_xlfn.IFERROR(VLOOKUP(L33,P1:R625,2,0),"")} | N33: {=_xlfn.IFERROR(VLOOKUP(L33,P1:R625,3,0),"")} | P33: Descontos Concedidos | Q33: Despesa Financeira | R33: 5.1 | Z33: PAGAMENTO PIX SICREDI 25481403854 MIRIAM RAQUEL | AA33: Salários e Encargos Administrativos
M34: {=_xlfn.IFERROR(VLOOKUP(L34,P1:R625,2,0),"")} | N34: {=_xlfn.IFERROR(VLOOKUP(L34,P1:R625,3,0),"")} | P34: Pró-Labore | Q34: Outros | R34: 4.3 | Z34: PAGAMENTO PIX 54774767883 Rafaela Claudino da Si | AA34: Salários e Encargos Administrativos
M35: {=_xlfn.IFERROR(VLOOKUP(L35,P1:R625,2,0),"")} | N35: {=_xlfn.IFERROR(VLOOKUP(L35,P1:R625,3,0),"")} | P35: Distribuição de Lucros | Q35: Outros | R35: 8 | Z35: SUB DB MASTER | EVOLUSERVI | 0001-26 | AA35: Receita de Vendas - Produtos
M36: {=_xlfn.IFERROR(VLOOKUP(L36,P1:R625,2,0),"")} | N36: {=_xlfn.IFERROR(VLOOKUP(L36,P1:R625,3,0),"")} | P36: Investimentos | Q36: Outros | R36: 7.1 | Z36: RECEBIMENTO PIX 01664924850 MARTA F.MASSARO | AA36: Receita de Vendas - Serviços
M37: {=_xlfn.IFERROR(VLOOKUP(L37,P1:R625,2,0),"")} | N37: {=_xlfn.IFERROR(VLOOKUP(L37,P1:R625,3,0),"")} | P37: Empréstimos e Financiamentos | Q37: Outros | R37: 7.3 | Z37: RECEBIMENTO PIX 05241466835 MARIA HELENA PEDRINA | AA37: Receita de Vendas - Serviços
M38: {=_xlfn.IFERROR(VLOOKUP(L38,P1:R625,2,0),"")} | N38: {=_xlfn.IFERROR(VLOOKUP(L38,P1:R625,3,0),"")} | P38: Provisões (13º, férias, etc.) | Q38: Outros | R38: 4.1 | Z38: MANUTENCAO DE TITULOS | AA38: Tarifas Bancárias
M39: {=_xlfn.IFERROR(VLOOKUP(L39,P1:R625,2,0),"")} | N39: {=_xlfn.IFERROR(VLOOKUP(L39,P1:R625,3,0),"")} | P39: Lançamentos a Identificar | Q39: Outros | R39: 8 | Z39: SUB CR VISA | SUMUP | 0001-26 | AA39: Receita de Vendas - Produtos
M40: {=_xlfn.IFERROR(VLOOKUP(L40,P1:R625,2,0),"")} | N40: {=_xlfn.IFERROR(VLOOKUP(L40,P1:R625,3,0),"")} | Z40: RECEBIMENTO PIX 39766716811 Debora Paina Alonso | AA40: Receita de Vendas - Serviços
M41: {=_xlfn.IFERROR(VLOOKUP(L41,P1:R625,2,0),"")} | N41: {=_xlfn.IFERROR(VLOOKUP(L41,P1:R625,3,0),"")} | Z41: PAGAMENTO PIX 09804828448 JOSE FERNANDO ALVES MA | AA41: Salários e Encargos Administrativos
M42: {=_xlfn.IFERROR(VLOOKUP(L42,P1:R625,2,0),"")} | N42: {=_xlfn.IFERROR(VLOOKUP(L42,P1:R625,3,0),"")} | Z42: PAGAMENTO PIX SICREDI 37405075000162 AJ MOVEIS E | AA42: Manutenção de Equipamentos
...

Sheet Base DRE Arquivo
